Workbook

Sheet EmpDetails
A1: Employee Code | B1: Full name | C1: Department | D1: Designation | F1: {=INDIRECT("T_EmpDetails[Full Name]")} -> Sandip Nivrutti Jadhav
A2: 00005 | B2: Sandip Nivrutti Jadhav | C2: Boiler | D2: Jr. Officer | F2: Pandit Mahadeo Hanjage
A3: 00006 | B3: Pandit Mahadeo Hanjage | C3: Production | D3: Officer | F3: Arvind Tanaji Devkar
A4: 00012 | B4: Arvind Tanaji Devkar | C4: PD Lab | D4: Officer | F4: Prashant Sukhdev Ingle
A5: 00014 | B5: Prashant Sukhdev Ingle | C5: HR | D5: HR Associate | F5: Ulhas Dilip Byale
A6: 00015 | B6: Ulhas Dilip Byale | C6: QC & QA | D6: Sr. Executive | F6: Savala Jagannath Kumbhar
A7: 00022 | B7: Savala Jagannath Kumbhar | C7: Electrical | D7: Executive | F7: Ravindra Vitthal Kashid
A8: 00030 | B8: Ravindra Vitthal Kashid | C8: Electrical | D8: Officer | F8: Shital Ramchandra Sathe
A9: 00032 | B9: Shital Ramchandra Sathe | C9: Production | D9: Production Associate | F9: Krishna Balaprasad Kushwaha
A10: 00035 | B10: Krishna Balaprasad Kushwaha | C10: Production | D10: Production Associate | F10: Shrishail Shantappa Mali
A11: 00039 | B11: Shrishail Shantappa Mali | C11: Maintenance | D11: Jr.Officer | F11: Arjun Guruling Wale
A12: 00041 | B12: Arjun Guruling Wale | C12: Production | D12: Asst.General Manager | F12: Amar Dattatray Paul
A13: 00042 | B13: Amar Dattatray Paul | C13: Production | D13: Jr.Officer | F13: Madhukar Balu Kambale
... A287: 01027 | B287: Sachin Chandrakant Padwal | C287: HR | D287: Asst.General Manager | F287: Vikas Mangilal Shah
A288: D0002 | B288: Vikas Mangilal Shah | C288: Management | D288: Director

Sheet Tables
A1: Department Name | C1: Consumable & Recurring Item | E1: Computer Equipment
A2: Boiler | C2: Brother Printer Toner Cartridge (Model HL-L2321D) | E2: COMPUTER CMOS CELL
A3: Production | C3: Canon G790 Black Ink Bottle | E3: COMPUTER MOUSE PAD | J3: Do not Delete OR Change
A4: PD Lab | C4: Canon G790 Cyan Ink Bottle | E4: External HDD
A5: HR | C5: Canon G790 Magenta Ink Bottle | E5: External SSD | J5: {=INDIRECT("DeptName01[Department Name]")} -> Boiler | K5: {=INDIRECT("Con_Rec_Item01[Consumable & Recurring Item]")} -> Brother Printer Toner Cartridge (Model HL-L2321D) | L5: {=INDIRECT("CompEquip01[Computer Equipment]")} -> COMPUTER CMOS CELL
A6: QC & QA | C6: Canon G790 Yellow Ink Bottle | E6: HDD | J6: Production | K6: Canon G790 Black Ink Bottle | L6: COMPUTER MOUSE PAD
A7: Project | C7: Canon Pixma Genuine Cartridge 70 Black | E7: Keyboard Wired | J7: PD Lab | K7: Canon G790 Cyan Ink Bottle | L7: External HDD
A8: Electrical | C8: Epson 003 Black Ink Bottle | E8: LAPTOP BATTERY | J8: HR | K8: Canon G790 Magenta Ink Bottle | L8: External SSD
A9: Maintenance | C9: Epson 003 Cyan Ink Bottle | E9: Mouse Pad | J9: QC & QA | K9: Canon G790 Yellow Ink Bottle | L9: HDD
A10: Quality Control | C10: Epson 003 Magenta Ink Bottle | E10: Mouse Wired | J10: Project | K10: Canon Pixma Genuine Cartridge 70 Black | L10: Keyboard Wired
A11: Accounts | C11: Epson 003 Yellow Ink Bottle | E11: Pendrive | J11: Electrical | K11: Epson 003 Black Ink Bottle | L11: LAPTOP BATTERY
A12: Admin | C12: Printer Toner Canon 12A Black | E12: POWER ADAPTER | J12: Maintenance | K12: Epson 003 Cyan Ink Bottle | L12: Mouse Pad
A13: EHS | C13: Printer Toner Cartridge 166A | E13: POWER CORD | J13: Quality Control | K13: Epson 003 Magenta Ink Bottle | L13: Mouse Wired
A14: Utility | C14: Printer Toner HP 88A Black | E14: Processor (CPU) Fan | J14: Accounts | K14: Epson 003 Yellow Ink Bottle | L14: Pendrive
A15: Store | E15: RAM | J15: Admin | K15: Printer Toner Canon 12A Black | L15: POWER ADAPTER
A16: Technical Services | E16: SMPS | J16: EHS | K16: Printer Toner Cartridge 166A | L16: POWER CORD
A17: SCM | E17: SSD (128 GB) | J17: Utility | K17: Printer Toner HP 88A Black | L17: Processor (CPU) Fan
A18: Purchase | E18: SSD (256 GB) | J18: Store | L18: RAM
A19: Instrument | E19: VGA TO HDMI CONVERTOR | J19: Technical Services | L19: SMPS
A20: Environment | E20: Wireless Keyboard | J20: SCM | L20: SSD (128 GB)
A21: Quality Assurance | E21: Wireless Mouse | J21: Purchase | L21: SSD (256 GB)
A22: IT | E22: Network Switch | J22: Instrument | L22: VGA TO HDMI CONVERTOR
A23: Engineering | J23: Environment | L23: Wireless Keyboard
A24: Operation | J24: Quality Assurance | L24: Wireless Mouse
A25: Management | J25: IT | L25: Network Switch
A26: Draftsman | J26: Engineering
A27: Engineering Store | J27: Operation
A28: Raw Store | J28: Management
A29: Security Gate E16 | J29: Draftsman
A30: Security Gate E22 | J30: Engineering Store
A31: Security Main Gate E17 | J31: Raw Store
A32: Security Main Gate E18 | J32: Security Gate E16
A33: Security Main Gate E18 | J33: Security Gate E22
J34: Security Main Gate E17
J35: Security Main Gate E18
J36: Security Main Gate E18

Sheet Recurring Item Re-Stock
A1: Sr. No | B1: Re-Stock Date | C1: Item Name | D1: Stock
A2: =ROW()-ROW($A$1) -> 1 | B2: 45491 | C2: Printer Toner HP 88A Black | D2: 10
A3: =ROW()-ROW($A$1) -> 2 | B3: 45496 | C3: Printer Toner HP 88A Black | D3: 5
A4: =ROW()-ROW($A$1) -> 3 | B4: 45604 | C4: Printer Toner HP 88A Black | D4: 15
A5: =ROW()-ROW($A$1) -> 4 | B5: 45698 | C5: Printer Toner HP 88A Black | D5: 10
A6: =ROW()-ROW($A$1) -> 5 | B6: 45713 | C6: Printer Toner HP 88A Black | D6: 5
A7: =ROW()-ROW($A$1) -> 6 | B7: 45763 | C7: Printer Toner HP 88A Black | D7: 9
A8: =ROW()-ROW($A$1) -> 7 | B8: 45763 | C8: Printer Toner Canon 12A Black | D8: 15
A9: =ROW()-ROW($A$1) -> 8 | B9: 45793 | C9: Printer Toner HP 88A Black | D9: 6
A10: =ROW()-ROW($A$1) -> 9 | B10: 45793 | C10: Canon Pixma Genuine Cartridge 70 Black | D10: 1
A11: =ROW()-ROW($A$1) -> 10 | B11: 45887 | C11: Printer Toner HP 88A Black | D11: 15
A12: =ROW()-ROW($A$1) -> 11 | B12: 45887 | C12: Epson 003 Black Ink Bottle | D12: 1
A13: =ROW()-ROW($A$1) -> 12 | B13: 45887 | C13: Epson 003 Cyan Ink Bottle | D13: 1
... A37: =ROW()-ROW($A$1) -> 36 | B37: 46245 | C37: Canon G790 Yellow Ink Bottle | D37: 1

Sheet Recurring Item
A1: Sr. No | B1: Item Name | C1: Stock | D1: Used | E1: Spare
A2: =ROW()-ROW(Rec_Stock01[[#Headers],[Sr. No]]) -> 1 | B2: Brother Printer Toner Cartridge (Model HL-L2321D) | C2: =SUMIF(Rec_ReStock01[Item Name],Rec_Stock01[[#This Row],[Item Name]],Rec_ReStock01[Stock]) -> 5 | D2: =SUMIF(Rec_Record01[Item Make],Rec_Stock01[[#This Row],[Item Name]],Rec_Record01[Qty. Used]) -> 4 | E2: =Rec_Stock01[[#This Row],[Stock]]-Rec_Stock01[[#This Row],[Used]] -> 1
A3: =ROW()-ROW(Rec_Stock01[[#Headers],[Sr. No]]) -> 2 | B3: Canon G790 Black Ink Bottle | C3: =SUMIF(Rec_ReStock01[Item Name],Rec_Stock01[[#This Row],[Item Name]],Rec_ReStock01[Stock]) -> 1 | D3: =SUMIF(Rec_Record01[Item Make],Rec_Stock01[[#This Row],[Item Name]],Rec_Record01[Qty. Used]) -> 0 | E3: =Rec_Stock01[[#This Row],[Stock]]-Rec_Stock01[[#This Row],[Used]] -> 1
A4: =ROW()-ROW(Rec_Stock01[[#Headers],[Sr. No]]) -> 3 | B4: Canon G790 Cyan Ink Bottle | C4: =SUMIF(Rec_ReStock01[Item Name],Rec_Stock01[[#This Row],[Item Name]],Rec_ReStock01[Stock]) -> 1 | D4: =SUMIF(Rec_Record01[Item Make],Rec_Stock01[[#This Row],[Item Name]],Rec_Record01[Qty. Used]) -> 0 | E4: =Rec_Stock01[[#This Row],[Stock]]-Rec_Stock01[[#This Row],[Used]] -> 1
A5: =ROW()-ROW(Rec_Stock01[[#Headers],[Sr. No]]) -> 4 | B5: Canon G790 Magenta Ink Bottle | C5: =SUMIF(Rec_ReStock01[Item Name],Rec_Stock01[[#This Row],[Item Name]],Rec_ReStock01[Stock]) -> 1 | D5: =SUMIF(Rec_Record01[Item Make],Rec_Stock01[[#This Row],[Item Name]],Rec_Record01[Qty. Used]) -> 0 | E5: =Rec_Stock01[[#This Row],[Stock]]-Rec_Stock01[[#This Row],[Used]] -> 1
A6: =ROW()-ROW(Rec_Stock01[[#Headers],[Sr. No]]) -> 5 | B6: Canon G790 Yellow Ink Bottle | C6: =SUMIF(Rec_ReStock01[Item Name],Rec_Stock01[[#This Row],[Item Name]],Rec_ReStock01[Stock]) -> 1 | D6: =SUMIF(Rec_Record01[Item Make],Rec_Stock01[[#This Row],[Item Name]],Rec_Record01[Qty. Used]) -> 0 | E6: =Rec_Stock01[[#This Row],[Stock]]-Rec_Stock01[[#This Row],[Used]] -> 1
A7: =ROW()-ROW(Rec_Stock01[[#Headers],[Sr. No]]) -> 6 | B7: Canon Pixma Genuine Cartridge 70 Black | C7: =SUMIF(Rec_ReStock01[Item Name],Rec_Stock01[[#This Row],[Item Name]],Rec_ReStock01[Stock]) -> 4 | D7: =SUMIF(Rec_Record01[Item Make],Rec_Stock01[[#This Row],[Item Name]],Rec_Record01[Qty. Used]) -> 3 | E7: =Rec_Stock01[[#This Row],[Stock]]-Rec_Stock01[[#This Row],[Used]] -> 1
A8: =ROW()-ROW(Rec_Stock01[[#Headers],[Sr. No]]) -> 7 | B8: Epson 003 Black Ink Bottle | C8: =SUMIF(Rec_ReStock01[Item Name],Rec_Stock01[[#This Row],[Item Name]],Rec_ReStock01[Stock]) -> 4 | D8: =SUMIF(Rec_Record01[Item Make],Rec_Stock01[[#This Row],[Item Name]],Rec_Record01[Qty. Used]) -> 1 | E8: =Rec_Stock01[[#This Row],[Stock]]-Rec_Stock01[[#This Row],[Used]] -> 3
A9: =ROW()-ROW(Rec_Stock01[[#Headers],[Sr. No]]) -> 8 | B9: Epson 003 Cyan Ink Bottle | C9: =SUMIF(Rec_ReStock01[Item Name],Rec_Stock01[[#This Row],[Item Name]],Rec_ReStock01[Stock]) -> 4 | D9: =SUMIF(Rec_Record01[Item Make],Rec_Stock01[[#This Row],[Item Name]],Rec_Record01[Qty. Used]) -> 1 | E9: =Rec_Stock01[[#This Row],[Stock]]-Rec_Stock01[[#This Row],[Used]] -> 3
A10: =ROW()-ROW(Rec_Stock01[[#Headers],[Sr. No]]) -> 9 | B10: Epson 003 Magenta Ink Bottle | C10: =SUMIF(Rec_ReStock01[Item Name],Rec_Stock01[[#This Row],[Item Name]],Rec_ReStock01[Stock]) -> 4 | D10: =SUMIF(Rec_Record01[Item Make],Rec_Stock01[[#This Row],[Item Name]],Rec_Record01[Qty. Used]) -> 1 | E10: =Rec_Stock01[[#This Row],[Stock]]-Rec_Stock01[[#This Row],[Used]] -> 3
A11: =ROW()-ROW(Rec_Stock01[[#Headers],[Sr. No]]) -> 10 | B11: Epson 003 Yellow Ink Bottle | C11: =SUMIF(Rec_ReStock01[Item Name],Rec_Stock01[[#This Row],[Item Name]],Rec_ReStock01[Stock]) -> 4 | D11: =SUMIF(Rec_Record01[Item Make],Rec_Stock01[[#This Row],[Item Name]],Rec_Record01[Qty. Used]) -> 1 | E11: =Rec_Stock01[[#This Row],[Stock]]-Rec_Stock01[[#This Row],[Used]] -> 3
A12: =ROW()-ROW(Rec_Stock01[[#Headers],[Sr. No]]) -> 11 | B12: Printer Toner Canon 12A Black | C12: =SUMIF(Rec_ReStock01[Item Name],Rec_Stock01[[#This Row],[Item Name]],Rec_ReStock01[Stock]) -> 25 | D12: =SUMIF(Rec_Record01[Item Make],Rec_Stock01[[#This Row],[Item Name]],Rec_Record01[Qty. Used]) -> 25 | E12: =Rec_Stock01[[#This Row],[Stock]]-Rec_Stock01[[#This Row],[Used]] -> 0
A13: =ROW()-ROW(Rec_Stock01[[#Headers],[Sr. No]]) -> 12 | B13: Printer Toner Cartridge 166A | C13: =SUMIF(Rec_ReStock01[Item Name],Rec_Stock01[[#This Row],[Item Name]],Rec_ReStock01[Stock]) -> 9 | D13: =SUMIF(Rec_Record01[Item Make],Rec_Stock01[[#This Row],[Item Name]],Rec_Record01[Qty. Used]) -> 7 | E13: =Rec_Stock01[[#This Row],[Stock]]-Rec_Stock01[[#This Row],[Used]] -> 2
A14: =ROW()-ROW(Rec_Stock01[[#Headers],[Sr. No]]) -> 13 | B14: Printer Toner HP 88A Black | C14: =SUMIF(Rec_ReStock01[Item Name],Rec_Stock01[[#This Row],[Item Name]],Rec_ReStock01[Stock]) -> 145 | D14: =SUMIF(Rec_Record01[Item Make],Rec_Stock01[[#This Row],[Item Name]],Rec_Record01[Qty. Used]) -> 137 | E14: =Rec_Stock01[[#This Row],[Stock]]-Rec_Stock01[[#This Row],[Used]] -> 8

Sheet Recurring Item Record
A1: Sr. No. | B1: Use Start Date | C1: Use End Date | D1: Department/User Name | E1: Item Make | F1: Qty. Used
A2: =ROW()-ROW($A$1) -> 1 | B2: 25-07-2024 | D2: Raw Store | E2: Printer Toner HP 88A Black | F2: 4
A3: =ROW()-ROW($A$1) -> 2 | B3: 25-07-2024 | D3: Quality Control | E3: Printer Toner HP 88A Black | F3: 2
A4: =ROW()-ROW($A$1) -> 3 | B4: 45505 | D4: Sachin Padvwal | E4: Printer Toner HP 88A Black | F4: 1
A5: =ROW()-ROW($A$1) -> 4 | B5: 45505 | D5: Accounts | E5: Printer Toner HP 88A Black | F5: 1
A6: =ROW()-ROW($A$1) -> 5 | B6: 45516 | D6: Quality Control | E6: Printer Toner HP 88A Black | F6: 1
A7: =ROW()-ROW($A$1) -> 6 | B7: 30-08-2024 | D7: Security Main Gate E18 | E7: Printer Toner HP 88A Black | F7: 1
A8: =ROW()-ROW($A$1) -> 7 | B8: 45551 | D8: E22 Utility Room (Vinayak Bagalkatti) | E8: Printer Toner HP 88A Black | F8: 1
A9: =ROW()-ROW($A$1) -> 8 | B9: 45560 | D9: Raw Store | E9: Printer Toner HP 88A Black | F9: 3
A10: =ROW()-ROW($A$1) -> 9 | B10: 45602 | D10: E17 Production | E10: Printer Toner HP 88A Black | F10: 1
A11: =ROW()-ROW($A$1) -> 10 | B11: 45604 | D11: Raw Store | E11: Printer Toner HP 88A Black | F11: 6
A12: =ROW()-ROW($A$1) -> 11 | B12: 45604 | D12: Security Main Gate E18 | E12: Printer Toner HP 88A Black | F12: 1
A13: =ROW()-ROW($A$1) -> 12 | B13: 45604 | D13: Quality Control | E13: Printer Toner HP 88A Black | F13: 2
A14: =ROW()-ROW($A$1) -> 13 | B14: 45637 | D14: E17 Production | E14: Printer Toner HP 88A Black | F14: 1
A15: =ROW()-ROW($A$1) -> 14 | B15: 45669 | D15: Security Main Gate E18 | E15: Printer Toner HP 88A Black | F15: 1
A16: =ROW()-ROW($A$1) -> 15 | B16: 45671 | D16: Quality Control | E16: Printer Toner HP 88A Black | F16: 1
A17: =ROW()-ROW($A$1) -> 16 | B17: 45671 | D17: Raw Store | E17: Printer Toner HP 88A Black | F17: 2
A18: =ROW()-ROW($A$1) -> 17 | B18: 45677 | D18: Accounts | E18: Printer Toner HP 88A Black | F18: 1
A19: =ROW()-ROW($A$1) -> 18 | B19: 45698 | D19: Raw Store | E19: Printer Toner HP 88A Black | F19: 5
... A96: =ROW()-ROW($A$1) -> 95 | B96: 46272 | D96: Production | E96: Printer Toner Cartridge 166A | F96: 1

Sheet Computer Equipment Re-Stock
A1: Sr. No | B1: Re-Stock Date | C1: Item Name | D1: Stock
A2: =ROW()-ROW($A$1) -> 1 | B2: 23-08-2024 | C2: Wireless Mouse | D2: 5
A3: =ROW()-ROW($A$1) -> 2 | B3: 22-11-2024 | C3: Keyboard Wired | D3: 3
A4: =ROW()-ROW($A$1) -> 3 | B4: 22-11-2024 | C4: Mouse Wired | D4: 3
A5: =ROW()-ROW($A$1) -> 4 | B5: 45651 | C5: Wireless Mouse | D5: 5
A6: =ROW()-ROW($A$1) -> 5 | B6: 45713 | C6: Keyboard Wired | D6: 10
A7: =ROW()-ROW($A$1) -> 6 | B7: 45713 | C7: Mouse Wired | D7: 10
A8: =ROW()-ROW($A$1) -> 7 | B8: 45749 | C8: Processor (CPU) Fan | D8: 1
A9: =ROW()-ROW($A$1) -> 8 | B9: 45866 | C9: SSD (128 GB) | D9: 2
A10: =ROW()-ROW($A$1) -> 9 | B10: 45866 | C10: SSD (256 GB) | D10: 2
A11: =ROW()-ROW($A$1) -> 10 | B11: 45866 | C11: Pendrive | D11: 1
A12: =ROW()-ROW($A$1) -> 11 | B12: 45887 | C12: Mouse Wired | D12: 3
A13: =ROW()-ROW($A$1) -> 12 | B13: 45887 | C13: Wireless Mouse | D13: 2
A14: =ROW()-ROW($A$1) -> 13 | B14: 45887 | C14: External HDD | D14: 1
A15: =ROW()-ROW($A$1) -> 14 | B15: 45887 | C15: Pendrive | D15: 1
A16: =ROW()-ROW($A$1) -> 15 | B16: 45887 | C16: LAPTOP BATTERY | D16: 1
... A26: =ROW()-ROW($A$1) -> 25 | B26: 46090 | C26: Wireless Mouse | D26: 2

Sheet Computer Equipments
A1: Sr. No. | B1: Item Name | C1: Stock | D1: Used | E1: Return | F1: Working | G1: Not Working | H1: Spare
A2: =ROW()-ROW($A$1) -> 1 | B2: COMPUTER CMOS CELL | C2: =SUMIF(Equip_ReStock01[Item Name],CompEquipTable01[[#This Row],[Item Name]],Equip_ReStock01[Stock]) -> 10 | D2: =SUMIFS(EquipRecord01[Qty. Used],EquipRecord01[Computer Equipment],CompEquipTable01[[#This Row],[Item Name]],EquipRecord01[Action],"Given to User") -> 0 | E2: =SUMIFS(EquipRecord01[Qty. Used],EquipRecord01[Computer Equipment],CompEquipTable01[[#This Row],[Item Name]],EquipRecord01[Action],"Return by User",EquipRecord01[Status],"<>Not Working") -> 0 | F2: =COUNTIFS(EquipRecord01[Computer Equipment],CompEquipTable01[[#This Row],[Item Name]],EquipRecord01[Status],"Working") -> 0 | G2: =COUNTIFS(EquipRecord01[Computer Equipment],CompEquipTable01[[#This Row],[Item Name]],EquipRecord01[Status],"Not Working") -> 0 | H2: =(CompEquipTable01[[#This Row],[Stock]])-(CompEquipTable01[[#This Row],[Used]]+CompEquipTable01[[#This Row],[Not Working]]) -> 10
A3: =ROW()-ROW($A$1) -> 2 | B3: COMPUTER MOUSE PAD | C3: =SUMIF(Equip_ReStock01[Item Name],CompEquipTable01[[#This Row],[Item Name]],Equip_ReStock01[Stock]) -> 10 | D3: =SUMIFS(EquipRecord01[Qty. Used],EquipRecord01[Computer Equipment],CompEquipTable01[[#This Row],[Item Name]],EquipRecord01[Action],"Given to User") -> 0 | E3: =SUMIFS(EquipRecord01[Qty. Used],EquipRecord01[Computer Equipment],CompEquipTable01[[#This Row],[Item Name]],EquipRecord01[Action],"Return by User",EquipRecord01[Status],"<>Not Working") -> 0 | F3: =COUNTIFS(EquipRecord01[Computer Equipment],CompEquipTable01[[#This Row],[Item Name]],EquipRecord01[Status],"Working") -> 0 | G3: =COUNTIFS(EquipRecord01[Computer Equipment],CompEquipTable01[[#This Row],[Item Name]],EquipRecord01[Status],"Not Working") -> 0 | H3: =(CompEquipTable01[[#This Row],[Stock]])-(CompEquipTable01[[#This Row],[Used]]+CompEquipTable01[[#This Row],[Not Working]]) -> 10
A4: =ROW()-ROW($A$1) -> 3 | B4: External HDD | C4: =SUMIF(Equip_ReStock01[Item Name],CompEquipTable01[[#This Row],[Item Name]],Equip_ReStock01[Stock]) -> 2 | D4: =SUMIFS(EquipRecord01[Qty. Used],EquipRecord01[Computer Equipment],CompEquipTable01[[#This Row],[Item Name]],EquipRecord01[Action],"Given to User") -> 1 | E4: =SUMIFS(EquipRecord01[Qty. Used],EquipRecord01[Computer Equipment],CompEquipTable01[[#This Row],[Item Name]],EquipRecord01[Action],"Return by User",EquipRecord01[Status],"<>Not Working") -> 0 | F4: =COUNTIFS(EquipRecord01[Computer Equipment],CompEquipTable01[[#This Row],[Item Name]],EquipRecord01[Status],"Working") -> 1 | G4: =COUNTIFS(EquipRecord01[Computer Equipment],CompEquipTable01[[#This Row],[Item Name]],EquipRecord01[Status],"Not Working") -> 0 | H4: =(CompEquipTable01[[#This Row],[Stock]])-(CompEquipTable01[[#This Row],[Used]]+CompEquipTable01[[#This Row],[Not Working]]) -> 1
A5: =ROW()-ROW($A$1) -> 4 | B5: External SSD | C5: =SUMIF(Equip_ReStock01[Item Name],CompEquipTable01[[#This Row],[Item Name]],Equip_ReStock01[Stock]) -> 0 | D5: =SUMIFS(EquipRecord01[Qty. Used],EquipRecord01[Computer Equipment],CompEquipTable01[[#This Row],[Item Name]],EquipRecord01[Action],"Given to User") -> 0 | E5: =SUMIFS(EquipRecord01[Qty. Used],EquipRecord01[Computer Equipment],CompEquipTable01[[#This Row],[Item Name]],EquipRecord01[Action],"Return by User",EquipRecord01[Status],"<>Not Working") -> 0 | F5: =COUNTIFS(EquipRecord01[Computer Equipment],CompEquipTable01[[#This Row],[Item Name]],EquipRecord01[Status],"Working") -> 0 | G5: =COUNTIFS(EquipRecord01[Computer Equipment],CompEquipTable01[[#This Row],[Item Name]],EquipRecord01[Status],"Not Working") -> 0 | H5: =(CompEquipTable01[[#This Row],[Stock]])-(CompEquipTable01[[#This Row],[Used]]+CompEquipTable01[[#This Row],[Not Working]]) -> 0
A6: =ROW()-ROW($A$1) -> 5 | B6: HDD | C6: =SUMIF(Equip_ReStock01[Item Name],CompEquipTable01[[#This Row],[Item Name]],Equip_ReStock01[Stock]) -> 0 | D6: =SUMIFS(EquipRecord01[Qty. Used],EquipRecord01[Computer Equipment],CompEquipTable01[[#This Row],[Item Name]],EquipRecord01[Action],"Given to User") -> 0 | E6: =SUMIFS(EquipRecord01[Qty. Used],EquipRecord01[Computer Equipment],CompEquipTable01[[#This Row],[Item Name]],EquipRecord01[Action],"Return by User",EquipRecord01[Status],"<>Not Working") -> 0 | F6: =COUNTIFS(EquipRecord01[Computer Equipment],CompEquipTable01[[#This Row],[Item Name]],EquipRecord01[Status],"Working") -> 0 | G6: =COUNTIFS(EquipRecord01[Computer Equipment],CompEquipTable01[[#This Row],[Item Name]],EquipRecord01[Status],"Not Working") -> 0 | H6: =(CompEquipTable01[[#This Row],[Stock]])-(CompEquipTable01[[#This Row],[Used]]+CompEquipTable01[[#This Row],[Not Working]]) -> 0
A7: =ROW()-ROW($A$1) -> 6 | B7: Keyboard Wired | C7: =SUMIF(Equip_ReStock01[Item Name],CompEquipTable01[[#This Row],[Item Name]],Equip_ReStock01[Stock]) -> 18 | D7: =SUMIFS(EquipRecord01[Qty. Used],EquipRecord01[Computer Equipment],CompEquipTable01[[#This Row],[Item Name]],EquipRecord01[Action],"Given to User") -> 13 | E7: =SUMIFS(EquipRecord01[Qty. Used],EquipRecord01[Computer Equipment],CompEquipTable01[[#This Row],[Item Name]],EquipRecord01[Action],"Return by User",EquipRecord01[Status],"<>Not Working") -> 0 | F7: =COUNTIFS(EquipRecord01[Computer Equipment],CompEquipTable01[[#This Row],[Item Name]],EquipRecord01[Status],"Working") -> 12 | G7: =COUNTIFS(EquipRecord01[Computer Equipment],CompEquipTable01[[#This Row],[Item Name]],EquipRecord01[Status],"Not Working") -> 0 | H7: =(CompEquipTable01[[#This Row],[Stock]])-(CompEquipTable01[[#This Row],[Used]]+CompEquipTable01[[#This Row],[Not Working]]) -> 5
A8: =ROW()-ROW($A$1) -> 7 | B8: LAPTOP BATTERY | C8: =SUMIF(Equip_ReStock01[Item Name],CompEquipTable01[[#This Row],[Item Name]],Equip_ReStock01[Stock]) -> 1 | D8: =SUMIFS(EquipRecord01[Qty. Used],EquipRecord01[Computer Equipment],CompEquipTable01[[#This Row],[Item Name]],EquipRecord01[Action],"Given to User") -> 1 | E8: =SUMIFS(EquipRecord01[Qty. Used],EquipRecord01[Computer Equipment],CompEquipTable01[[#This Row],[Item Name]],EquipRecord01[Action],"Return by User",EquipRecord01[Status],"<>Not Working") -> 0 | F8: =COUNTIFS(EquipRecord01[Computer Equipment],CompEquipTable01[[#This Row],[Item Name]],EquipRecord01[Status],"Working") -> 1 | G8: =COUNTIFS(EquipRecord01[Computer Equipment],CompEquipTable01[[#This Row],[Item Name]],EquipRecord01[Status],"Not Working") -> 0 | H8: =(CompEquipTable01[[#This Row],[Stock]])-(CompEquipTable01[[#This Row],[Used]]+CompEquipTable01[[#This Row],[Not Working]]) -> 0
A9: =ROW()-ROW($A$1) -> 8 | B9: Mouse Pad | C9: =SUMIF(Equip_ReStock01[Item Name],CompEquipTable01[[#This Row],[Item Name]],Equip_ReStock01[Stock]) -> 0 | D9: =SUMIFS(EquipRecord01[Qty. Used],EquipRecord01[Computer Equipment],CompEquipTable01[[#This Row],[Item Name]],EquipRecord01[Action],"Given to User") -> 0 | E9: =SUMIFS(EquipRecord01[Qty. Used],EquipRecord01[Computer Equipment],CompEquipTable01[[#This Row],[Item Name]],EquipRecord01[Action],"Return by User",EquipRecord01[Status],"<>Not Working") -> 0 | F9: =COUNTIFS(EquipRecord01[Computer Equipment],CompEquipTable01[[#This Row],[Item Name]],EquipRecord01[Status],"Working") -> 0 | G9: =COUNTIFS(EquipRecord01[Computer Equipment],CompEquipTable01[[#This Row],[Item Name]],EquipRecord01[Status],"Not Working") -> 0 | H9: =(CompEquipTable01[[#This Row],[Stock]])-(CompEquipTable01[[#This Row],[Used]]+CompEquipTable01[[#This Row],[Not Working]]) -> 0
A10: =ROW()-ROW($A$1) -> 9 | B10: Mouse Wired | C10: =SUMIF(Equip_ReStock01[Item Name],CompEquipTable01[[#This Row],[Item Name]],Equip_ReStock01[Stock]) -> 21 | D10: =SUMIFS(EquipRecord01[Qty. Used],EquipRecord01[Computer Equipment],CompEquipTable01[[#This Row],[Item Name]],EquipRecord01[Action],"Given to User") -> 16 | E10: =SUMIFS(EquipRecord01[Qty. Used],EquipRecord01[Computer Equipment],CompEquipTable01[[#This Row],[Item Name]],EquipRecord01[Action],"Return by User",EquipRecord01[Status],"<>Not Working") -> 0 | F10: =COUNTIFS(EquipRecord01[Computer Equipment],CompEquipTable01[[#This Row],[Item Name]],EquipRecord01[Status],"Working") -> 15 | G10: =COUNTIFS(EquipRecord01[Computer Equipment],CompEquipTable01[[#This Row],[Item Name]],EquipRecord01[Status],"Not Working") -> 0 | H10: =(CompEquipTable01[[#This Row],[Stock]])-(CompEquipTable01[[#This Row],[Used]]+CompEquipTable01[[#This Row],[Not Working]]) -> 5
A11: =ROW()-ROW($A$1) -> 10 | B11: Pendrive | C11: =SUMIF(Equip_ReStock01[Item Name],CompEquipTable01[[#This Row],[Item Name]],Equip_ReStock01[Stock]) -> 2 | D11: =SUMIFS(EquipRecord01[Qty. Used],EquipRecord01[Computer Equipment],CompEquipTable01[[#This Row],[Item Name]],EquipRecord01[Action],"Given to User") -> 1 | E11: =SUMIFS(EquipRecord01[Qty. Used],EquipRecord01[Computer Equipment],CompEquipTable01[[#This Row],[Item Name]],EquipRecord01[Action],"Return by User",EquipRecord01[Status],"<>Not Working") -> 0 | F11: =COUNTIFS(EquipRecord01[Computer Equipment],CompEquipTable01[[#This Row],[Item Name]],EquipRecord01[Status],"Working") -> 1 | G11: =COUNTIFS(EquipRecord01[Computer Equipment],CompEquipTable01[[#This Row],[Item Name]],EquipRecord01[Status],"Not Working") -> 0 | H11: =(CompEquipTable01[[#This Row],[Stock]])-(CompEquipTable01[[#This Row],[Used]]+CompEquipTable01[[#This Row],[Not Working]]) -> 1
A12: =ROW()-ROW($A$1) -> 11 | B12: POWER ADAPTER | C12: =SUMIF(Equip_ReStock01[Item Name],CompEquipTable01[[#This Row],[Item Name]],Equip_ReStock01[Stock]) -> 0 | D12: =SUMIFS(EquipRecord01[Qty. Used],EquipRecord01[Computer Equipment],CompEquipTable01[[#This Row],[Item Name]],EquipRecord01[Action],"Given to User") -> 0 | E12: =SUMIFS(EquipRecord01[Qty. Used],EquipRecord01[Computer Equipment],CompEquipTable01[[#This Row],[Item Name]],EquipRecord01[Action],"Return by User",EquipRecord01[Status],"<>Not Working") -> 0 | F12: =COUNTIFS(EquipRecord01[Computer Equipment],CompEquipTable01[[#This Row],[Item Name]],EquipRecord01[Status],"Working") -> 0 | G12: =COUNTIFS(EquipRecord01[Computer Equipment],CompEquipTable01[[#This Row],[Item Name]],EquipRecord01[Status],"Not Working") -> 0 | H12: =(CompEquipTable01[[#This Row],[Stock]])-(CompEquipTable01[[#This Row],[Used]]+CompEquipTable01[[#This Row],[Not Working]]) -> 0
A13: =ROW()-ROW($A$1) -> 12 | B13: POWER CORD | C13: =SUMIF(Equip_ReStock01[Item Name],CompEquipTable01[[#This Row],[Item Name]],Equip_ReStock01[Stock]) -> 3 | D13: =SUMIFS(EquipRecord01[Qty. Used],EquipRecord01[Computer Equipment],CompEquipTable01[[#This Row],[Item Name]],EquipRecord01[Action],"Given to User") -> 0 | E13: =SUMIFS(EquipRecord01[Qty. Used],EquipRecord01[Computer Equipment],CompEquipTable01[[#This Row],[Item Name]],EquipRecord01[Action],"Return by User",EquipRecord01[Status],"<>Not Working") -> 0 | F13: =COUNTIFS(EquipRecord01[Computer Equipment],CompEquipTable01[[#This Row],[Item Name]],EquipRecord01[Status],"Working") -> 0 | G13: =COUNTIFS(EquipRecord01[Computer Equipment],CompEquipTable01[[#This Row],[Item Name]],EquipRecord01[Status],"Not Working") -> 0 | H13: =(CompEquipTable01[[#This Row],[Stock]])-(CompEquipTable01[[#This Row],[Used]]+CompEquipTable01[[#This Row],[Not Working]]) -> 3
... A21: =ROW()-ROW($A$1) -> 20 | B21: Wireless Mouse | C21: =SUMIF(Equip_ReStock01[Item Name],CompEquipTable01[[#This Row],[Item Name]],Equip_ReStock01[Stock]) -> 14 | D21: =SUMIFS(EquipRecord01[Qty. Used],EquipRecord01[Computer Equipment],CompEquipTable01[[#This Row],[Item Name]],EquipRecord01[Action],"Given to User") -> 13 | E21: =SUMIFS(EquipRecord01[Qty. Used],EquipRecord01[Computer Equipment],CompEquipTable01[[#This Row],[Item Name]],EquipRecord01[Action],"Return by User",EquipRecord01[Status],"<>Not Working") -> 0 | F21: =COUNTIFS(EquipRecord01[Computer Equipment],CompEquipTable01[[#This Row],[Item Name]],EquipRecord01[Status],"Working") -> 13 | G21: =COUNTIFS(EquipRecord01[Computer Equipment],CompEquipTable01[[#This Row],[Item Name]],EquipRecord01[Status],"Not Working") -> 0 | H21: =(CompEquipTable01[[#This Row],[Stock]])-(CompEquipTable01[[#This Row],[Used]]+CompEquipTable01[[#This Row],[Not Working]]) -> 1

Sheet Computer Equipment Record
A1: Sr. No. | B1: Date | C1: Name | D1: Department | E1: Computer Equipment | F1: Qty. Used | G1: Action | H1: Status | I1: Remark
A2: =ROW()-ROW($A$1) -> 1 | B2: 23-08-2024 | C2: Mahesh Dhondiba Hanchate | D2: =IFERROR(VLOOKUP(EquipRecord01[[#This Row],[Name]],EmpDetails!$B:$D,2,FALSE),"") -> Accounts | E2: Wireless Mouse | F2: 1 | G2: Given to User | H2: Working
A3: =ROW()-ROW($A$1) -> 2 | B3: 23-08-2024 | C3: Dattatray Deepak Chavan | D3: =IFERROR(VLOOKUP(EquipRecord01[[#This Row],[Name]],EmpDetails!$B:$D,2,FALSE),"") -> Maintenance | E3: Wireless Mouse | F3: 1 | G3: Given to User | H3: Working | I3: Replaced with damaged one
A4: =ROW()-ROW($A$1) -> 3 | B4: 25-10-2024 | C4: Vitthal Thorat | D4: HR | E4: Wireless Mouse | F4: 1 | G4: Given to User | H4: Working | I4: Replaced with damaged one
A5: =ROW()-ROW($A$1) -> 4 | B5: 45561 | C5: Avinash Hanmantu Naik | D5: =IFERROR(VLOOKUP(EquipRecord01[[#This Row],[Name]],EmpDetails!$B:$D,2,FALSE),"") -> Technical Services | E5: Wireless Mouse | F5: 1 | G5: Given to User | H5: Working | I5: Replaced with damaged one
A6: =ROW()-ROW($A$1) -> 5 | B6: 45629 | C6: Anand Shrikant Kanaka | D6: =IFERROR(VLOOKUP(EquipRecord01[[#This Row],[Name]],EmpDetails!$B:$D,2,FALSE),"") -> HR | E6: Wireless Mouse | F6: 1 | G6: Given to User | H6: Working | I6: Replaced with damaged one
A7: =ROW()-ROW($A$1) -> 6 | B7: 23-11-2024 | C7: Samadhan Kalyan Wabale | D7: =IFERROR(VLOOKUP(EquipRecord01[[#This Row],[Name]],EmpDetails!$B:$D,2,FALSE),"") -> Quality Assurance | E7: Keyboard Wired | F7: 1 | G7: Given to User | H7: Working | I7: Replaced with damaged one
A8: =ROW()-ROW($A$1) -> 7 | B8: 23-11-2024 | C8: Dayanand Rajshekhar Majage | D8: =IFERROR(VLOOKUP(EquipRecord01[[#This Row],[Name]],EmpDetails!$B:$D,2,FALSE),"") -> Production | E8: Keyboard Wired | F8: 1 | G8: Given to User | H8: Working | I8: Replaced with damaged one
A9: =ROW()-ROW($A$1) -> 8 | B9: 27-11-2024 | C9: E18 Security Gate | D9: Security Main Gate E18 | E9: Mouse Wired | F9: 1 | G9: Given to User | H9: Working | I9: Replaced with damaged one
A10: =ROW()-ROW($A$1) -> 9 | B10: 45639 | C10: Preetamkumar Sunil Abute | D10: =IFERROR(VLOOKUP(EquipRecord01[[#This Row],[Name]],EmpDetails!$B:$D,2,FALSE),"") -> Maintenance | E10: Mouse Wired | F10: 1 | G10: Given to User | H10: Working | I10: Replaced with damaged one
A11: =ROW()-ROW($A$1) -> 10 | B11: 45642 | C11: Ravindra Vitthal Kashid | D11: =IFERROR(VLOOKUP(EquipRecord01[[#This Row],[Name]],EmpDetails!$B:$D,2,FALSE),"") -> Electrical | E11: Mouse Wired | F11: 1 | G11: Given to User | H11: Working | I11: Replaced with damaged one
A12: =ROW()-ROW($A$1) -> 11 | B12: 45651 | C12: Vinod Umashankar Nimbalkar | D12: =IFERROR(VLOOKUP(EquipRecord01[[#This Row],[Name]],EmpDetails!$B:$D,2,FALSE),"") -> Quality Control | E12: Wireless Mouse | F12: 1 | G12: Given to User | H12: Working | I12: Replaced with damaged one
A13: =ROW()-ROW($A$1) -> 12 | B13: 45653 | C13: Bhagavan Vishnu Bhange | D13: =IFERROR(VLOOKUP(EquipRecord01[[#This Row],[Name]],EmpDetails!$B:$D,2,FALSE),"") -> EHS | E13: Wireless Mouse | F13: 1 | G13: Given to User | H13: Working | I13: Replaced with damaged one
A14: =ROW()-ROW($A$1) -> 13 | B14: 45667 | C14: Anand Shrikant Kanaka | D14: =IFERROR(VLOOKUP(EquipRecord01[[#This Row],[Name]],EmpDetails!$B:$D,2,FALSE),"") -> HR | E14: Wireless Mouse | F14: 1 | G14: Given to User | H14: Working | I14: Anand Kanaka Mystery
A15: =ROW()-ROW($A$1) -> 14 | B15: 45707 | C15: Vishvajit Shivdas Nalawade | D15: =IFERROR(VLOOKUP(EquipRecord01[[#This Row],[Name]],EmpDetails!$B:$D,2,FALSE),"") -> Technical Services | E15: Wireless Mouse | F15: 1 | G15: Given to User | H15: Working
A16: =ROW()-ROW($A$1) -> 15 | B16: 45712 | C16: Piyush Dhanrajji Kapse | D16: =IFERROR(VLOOKUP(EquipRecord01[[#This Row],[Name]],EmpDetails!$B:$D,2,FALSE),"") -> Production | E16: Wireless Mouse | F16: 1 | G16: Given to User | H16: Working
A17: =ROW()-ROW($A$1) -> 16 | B17: 45713 | C17: Nitesh Ishwar Mahadik | D17: =IFERROR(VLOOKUP(EquipRecord01[[#This Row],[Name]],EmpDetails!$B:$D,2,FALSE),"") -> EHS | E17: Keyboard Wired | F17: 1 | G17: Given to User | H17: Working | I17: Replaced with damaged one
A18: =ROW()-ROW($A$1) -> 17 | B18: 45713 | C18: Suraj Shinde | D18: Engineering Store | E18: Keyboard Wired | F18: 1 | G18: Given to User | H18: Working | I18: Replaced with damaged one
A19: =ROW()-ROW($A$1) -> 18 | B19: 45713 | C19: Suraj Shinde | D19: Engineering Store | E19: Mouse Wired | F19: 2 | G19: Given to User | H19: Working | I19: Replaced with damaged one
A20: =ROW()-ROW($A$1) -> 19 | B20: 45715 | C20: Stack Monitoring PC | D20: Boiler | E20: Keyboard Wired | F20: 1 | G20: Given to User | H20: Working | I20: Replaced with damaged one
A21: =ROW()-ROW($A$1) -> 20 | B21: 45715 | C21: Stack Monitoring PC | D21: Boiler | E21: Mouse Wired | F21: 1 | G21: Given to User | H21: Working | I21: Replaced with damaged one
A22: =ROW()-ROW($A$1) -> 21 | B22: 45715 | C22: Umesh Ramchandra Waichal | D22: =IFERROR(VLOOKUP(EquipRecord01[[#This Row],[Name]],EmpDetails!$B:$D,2,FALSE),"") -> Technical Services | E22: Mouse Wired | F22: 1 | G22: Given to User | H22: Working | I22: Replaced with damaged one
A23: =ROW()-ROW($A$1) -> 22 | B23: 45715 | C23: Sachin Shivasharan Chhure | D23: =IFERROR(VLOOKUP(EquipRecord01[[#This Row],[Name]],EmpDetails!$B:$D,2,FALSE),"") -> Instrument | E23: Mouse Wired | F23: 1 | G23: Given to User | H23: Working | I23: Replaced with damaged one
A24: =ROW()-ROW($A$1) -> 23 | B24: 45715 | C24: Savala Jagannath Kumbhar | D24: =IFERROR(VLOOKUP(EquipRecord01[[#This Row],[Name]],EmpDetails!$B:$D,2,FALSE),"") -> Electrical | E24: Mouse Wired | F24: 1 | G24: Given to User | H24: Working | I24: Replaced with damaged one
A25: =ROW()-ROW($A$1) -> 24 | B25: 45749 | C25: Dhiraj Mane | D25: HR | E25: Processor (CPU) Fan | F25: 1 | G25: Given to User | H25: Working | I25: Replaced with damaged one
A26: =ROW()-ROW($A$1) -> 25 | B26: 45755 | C26: E18 Security Gate | D26: Security Main Gate E18 | E26: Mouse Wired | F26: 1 | G26: Given to User | H26: Working | I26: Replaced with damaged one
A27: =ROW()-ROW($A$1) -> 26 | B27: 45779 | C27: Vinayak Shankar Bagalatti | D27: =IFERROR(VLOOKUP(EquipRecord01[[#This Row],[Name]],EmpDetails!$B:$D,2,FALSE),"") -> Utility | E27: Mouse Wired | F27: 1 | G27: Given to User | H27: Working | I27: Replaced with damaged one
A28: =ROW()-ROW($A$1) -> 27 | B28: 45806 | C28: Vijayashri Sidramappa Karande | D28: =IFERROR(VLOOKUP(EquipRecord01[[#This Row],[Name]],EmpDetails!$B:$D,2,FALSE),"") -> Accounts | E28: Mouse Wired | F28: 1 | G28: Given to User | H28: Working | I28: Replaced with damaged one
A29: =ROW()-ROW($A$1) -> 28 | B29: 45780 | C29: Account | D29: Accounts | E29: Mouse Wired | F29: 1 | G29: Given to User | H29: Working | I29: Replaced with damaged one
A30: =ROW()-ROW($A$1) -> 29 | B30: 45873 | C30: Samadhan Kalyan Wabale | D30: =IFERROR(VLOOKUP(EquipRecord01[[#This Row],[Name]],EmpDetails!$B:$D,2,FALSE),"") -> Quality Assurance | E30: Keyboard Wired | F30: 2 | G30: Given to User | H30: Working | I30: Replaced with damaged one
A31: =ROW()-ROW($A$1) -> 30 | B31: 45874 | C31: Rahul Sanjivan Kharadkar | D31: =IFERROR(VLOOKUP(EquipRecord01[[#This Row],[Name]],EmpDetails!$B:$D,2,FALSE),"") -> Technical Services | E31: Keyboard Wired | F31: 1 | G31: Given to User | H31: Working | I31: Replaced with damaged one
A32: =ROW()-ROW($A$1) -> 31 | B32: 45874 | C32: Rajkumar Mallikarjun Wagdari | D32: =IFERROR(VLOOKUP(EquipRecord01[[#This Row],[Name]],EmpDetails!$B:$D,2,FALSE),"") -> Purchase | E32: SSD (128 GB) | F32: 1 | G32: Given to User | H32: Working
A33: =ROW()-ROW($A$1) -> 32 | B33: 45875 | C33: Sachin Chandrakant Padwal | D33: =IFERROR(VLOOKUP(EquipRecord01[[#This Row],[Name]],EmpDetails!$B:$D,2,FALSE),"") -> HR | E33: Pendrive | F33: 1 | G33: Given to User | H33: Working | I33: 32 GB Pendrive (for Vitthal Thorat Sir Laptop Backup)
A34: =ROW()-ROW($A$1) -> 33 | B34: 45876 | C34: E16 Security Gate | D34: Security Gate E16 | E34: Keyboard Wired | F34: 1 | G34: Given to User | H34: Working | I34: Replaced with damaged one
A35: =ROW()-ROW($A$1) -> 34 | B35: 45876 | C35: E17 Instrument | D35: Instrument | E35: Keyboard Wired | F35: 1 | G35: Given to User | H35: Working | I35: Replaced with damaged one
A36: =ROW()-ROW($A$1) -> 35 | B36: 45882 | C36: Ganesh Shivaji Niture | D36: =IFERROR(VLOOKUP(EquipRecord01[[#This Row],[Name]],EmpDetails!$B:$D,2,FALSE),"") -> Maintenance | E36: Keyboard Wired | F36: 1 | G36: Given to User | H36: Working | I36: Replaced with damaged one
A37: =ROW()-ROW($A$1) -> 36 | B37: 45882 | C37: Yogesh Laxmaiah Ailolla | D37: =IFERROR(VLOOKUP(EquipRecord01[[#This Row],[Name]],EmpDetails!$B:$D,2,FALSE),"") -> Project | E37: Keyboard Wired | F37: 1 | G37: Given to User | H37: Working | I37: Replaced with damaged one
A38: =ROW()-ROW($A$1) -> 37 | B38: 45882 | C38: Yogesh Laxmaiah Ailolla | D38: =IFERROR(VLOOKUP(EquipRecord01[[#This Row],[Name]],EmpDetails!$B:$D,2,FALSE),"") -> Project | E38: SSD (256 GB) | F38: 1 | G38: Given to User | H38: Working
A39: =ROW()-ROW($A$1) -> 38 | B39: 45888 | C39: E17 Instrument (in DCS Room) | D39: Instrument | E39: Mouse Wired | F39: 1 | G39: Given to User | H39: Working | I39: Replaced with damaged one
A40: =ROW()-ROW($A$1) -> 39 | B40: 45888 | C40: PD Lab | D40: PD Lab | E40: Mouse Wired | F40: 1 | G40: Given to User | H40: Working | I40: Replaced with damaged one
...
