Workbook

Sheet Info
A1: SIM Type
A2: Nano SIM
A3: Standard SIM card
A4: Mini SIM
A5: eSiM
A6: Integrated SIM
A7: Nano SIM vs Micro SIM
A8: Micro SIM
A9: 3FF SIM card
A10: MFF2 SIM card
A11: Standard SIM
A12: Comparing Sim Card Sizes
... A17: Full SIM card

Sheet EMP Info
A1: Employee Code | B1: Full name | C1: Department | D1: Designation
A2: 00005 | B2: Sandip Nivrutti Jadhav | C2: Boiler | D2: Jr. Officer
A3: 00006 | B3: Pandit Mahadeo Hanjage | C3: Production | D3: Officer
A4: 00012 | B4: Arvind Tanaji Devkar | C4: PD Lab | D4: Officer
A5: 00014 | B5: Prashant Sukhdev Ingle | C5: HR | D5: HR Associate
A6: 00015 | B6: Ulhas Dilip Byale | C6: QC & QA | D6: Sr. Executive
A7: 00022 | B7: Savala Jagannath Kumbhar | C7: Electrical | D7: Executive
A8: 00030 | B8: Ravindra Vitthal Kashid | C8: Electrical | D8: Officer
A9: 00032 | B9: Shital Ramchandra Sathe | C9: Production | D9: Production Associate
A10: 00035 | B10: Krishna Balaprasad Kushwaha | C10: Production | D10: Production Associate
A11: 00039 | B11: Shrishail Shantappa Mali | C11: Maintenance | D11: Jr.Officer
A12: 00041 | B12: Arjun Guruling Wale | C12: Production | D12: Asst.General Manager
... A302: D0002 | B302: Vikas Mangilal Shah | C302: Management | D302: Director

Sheet VI
A1: Sr. No. | B1: Mobile Number | C1: Employee Code | D1: Employee Name | E1: Employee Dept. | F1: Sub User / Area of Uses | G1: Old Employee Name | H1: Old Employee Dept. | I1: Mobile Type | J1: Mobile Make & Model | K1: Purchase Date | L1: In Warranty | M1: Warranty Date | N1: Purchase From | O1: IMEI_1 | P1: IMEI_2 | Q1: Battery Number | R1: Sim Type | S1: SIM ID No. | T1: SIM 2 ID No. | U1: Mobile Number Status | V1: Remark
A2: =ROW()-ROW(Vi_SIM_Mobile[[#Headers],[Sr. No.]]) -> 1 | B2: 9371091004 | C2: 0 | D2: =IF(Vi_SIM_Mobile[[#This Row],[Employee Code]]=0,"-",IFERROR(IF(INDEX('EMP Info'!$B:$B, MATCH(TEXT(Vi_SIM_Mobile[[#This Row],[Employee Code]],"00000"), 'EMP Info'!$A:$A, 0))=0,"",INDEX('EMP Info'!$B:$B, MATCH(TEXT(Vi_SIM_Mobile[[#This Row],[Employee Code]],"00000"), 'EMP Info'!$A:$A, 0))),IFERROR(VLOOKUP(TEXT(Vi_SIM_Mobile[[#This Row],[Employee Code]],"00000"), 'EMP Info'!$A:$D, 2, FALSE) & " (" & VLOOKUP(TEXT(Vi_SIM_Mobile[[#This Row],[Employee Code]],"00000"), 'EMP Info'!$A:$D,4, FALSE) & ")",""))) -> - | E2: =IF(Vi_SIM_Mobile[[#This Row],[Employee Code]]=0,"-",IFERROR(IF(INDEX('EMP Info'!$C:$C, MATCH(TEXT(Vi_SIM_Mobile[[#This Row],[Employee Code]],"00000"), 'EMP Info'!$A:$A, 0))=0,"",INDEX('EMP Info'!$C:$C, MATCH(TEXT(Vi_SIM_Mobile[[#This Row],[Employee Code]],"00000"), 'EMP Info'!$A:$A, 0))),IFERROR(VLOOKUP(TEXT(Vi_SIM_Mobile[[#This Row],[Employee Code]],"00000"), 'EMP Info'!$A:$D, 2, FALSE) & " (" & VLOOKUP(TEXT(Vi_SIM_Mobile[[#This Row],[Employee Code]],"00000"), 'EMP Info'!$A:$D,4, FALSE) & ")",""))) -> - | I2: Basic Keypad Phone | J2: Itel | L2: =IFERROR(IF(Vi_SIM_Mobile[[#This Row],[Warranty Date]]<TODAY(), "Out of Warranty", IF(Vi_SIM_Mobile[[#This Row],[Warranty Date]]-TODAY()<=30, "Expiring Soon", "In Warranty")),"-") -> - | M2: =IFERROR(IF(Vi_SIM_Mobile[[#This Row],[Purchase Date]]="","NA",EDATE(Vi_SIM_Mobile[[#This Row],[Purchase Date]],12)),"NA") -> NA | S2: 89910273409140972230 | U2: Activated
A3: =ROW()-ROW(Vi_SIM_Mobile[[#Headers],[Sr. No.]]) -> 2 | B3: 9371091006 | D3: =IF(Vi_SIM_Mobile[[#This Row],[Employee Code]]=0,"-",IFERROR(IF(INDEX('EMP Info'!$B:$B, MATCH(TEXT(Vi_SIM_Mobile[[#This Row],[Employee Code]],"00000"), 'EMP Info'!$A:$A, 0))=0,"",INDEX('EMP Info'!$B:$B, MATCH(TEXT(Vi_SIM_Mobile[[#This Row],[Employee Code]],"00000"), 'EMP Info'!$A:$A, 0))),IFERROR(VLOOKUP(TEXT(Vi_SIM_Mobile[[#This Row],[Employee Code]],"00000"), 'EMP Info'!$A:$D, 2, FALSE) & " (" & VLOOKUP(TEXT(Vi_SIM_Mobile[[#This Row],[Employee Code]],"00000"), 'EMP Info'!$A:$D,4, FALSE) & ")",""))) -> - | E3: =IF(Vi_SIM_Mobile[[#This Row],[Employee Code]]=0,"-",IFERROR(IF(INDEX('EMP Info'!$C:$C, MATCH(TEXT(Vi_SIM_Mobile[[#This Row],[Employee Code]],"00000"), 'EMP Info'!$A:$A, 0))=0,"",INDEX('EMP Info'!$C:$C, MATCH(TEXT(Vi_SIM_Mobile[[#This Row],[Employee Code]],"00000"), 'EMP Info'!$A:$A, 0))),IFERROR(VLOOKUP(TEXT(Vi_SIM_Mobile[[#This Row],[Employee Code]],"00000"), 'EMP Info'!$A:$D, 2, FALSE) & " (" & VLOOKUP(TEXT(Vi_SIM_Mobile[[#This Row],[Employee Code]],"00000"), 'EMP Info'!$A:$D,4, FALSE) & ")",""))) -> - | J3: - | L3: =IFERROR(IF(Vi_SIM_Mobile[[#This Row],[Warranty Date]]<TODAY(), "Out of Warranty", IF(Vi_SIM_Mobile[[#This Row],[Warranty Date]]-TODAY()<=30, "Expiring Soon", "In Warranty")),"-") -> - | M3: =IFERROR(IF(Vi_SIM_Mobile[[#This Row],[Purchase Date]]="","NA",EDATE(Vi_SIM_Mobile[[#This Row],[Purchase Date]],12)),"NA") -> NA | U3: Inactive
A4: =ROW()-ROW(Vi_SIM_Mobile[[#Headers],[Sr. No.]]) -> 3 | B4: 9371091014 | C4: 473 | D4: =IF(Vi_SIM_Mobile[[#This Row],[Employee Code]]=0,"-",IFERROR(IF(INDEX('EMP Info'!$B:$B, MATCH(TEXT(Vi_SIM_Mobile[[#This Row],[Employee Code]],"00000"), 'EMP Info'!$A:$A, 0))=0,"",INDEX('EMP Info'!$B:$B, MATCH(TEXT(Vi_SIM_Mobile[[#This Row],[Employee Code]],"00000"), 'EMP Info'!$A:$A, 0))),IFERROR(VLOOKUP(TEXT(Vi_SIM_Mobile[[#This Row],[Employee Code]],"00000"), 'EMP Info'!$A:$D, 2, FALSE) & " (" & VLOOKUP(TEXT(Vi_SIM_Mobile[[#This Row],[Employee Code]],"00000"), 'EMP Info'!$A:$D,4, FALSE) & ")",""))) -> Bhagyawan Chandrakant Gaikwad | E4: =IF(Vi_SIM_Mobile[[#This Row],[Employee Code]]=0,"-",IFERROR(IF(INDEX('EMP Info'!$C:$C, MATCH(TEXT(Vi_SIM_Mobile[[#This Row],[Employee Code]],"00000"), 'EMP Info'!$A:$A, 0))=0,"",INDEX('EMP Info'!$C:$C, MATCH(TEXT(Vi_SIM_Mobile[[#This Row],[Employee Code]],"00000"), 'EMP Info'!$A:$A, 0))),IFERROR(VLOOKUP(TEXT(Vi_SIM_Mobile[[#This Row],[Employee Code]],"00000"), 'EMP Info'!$A:$D, 2, FALSE) & " (" & VLOOKUP(TEXT(Vi_SIM_Mobile[[#This Row],[Employee Code]],"00000"), 'EMP Info'!$A:$D,4, FALSE) & ")",""))) -> Production | F4: Self | G4: - | H4: - | I4: Smartphone | J4: Samsung A16 | K4: 45900 | L4: =IFERROR(IF(Vi_SIM_Mobile[[#This Row],[Warranty Date]]<TODAY(), "Out of Warranty", IF(Vi_SIM_Mobile[[#This Row],[Warranty Date]]-TODAY()<=30, "Expiring Soon", "In Warranty")),"-") -> Out of Warranty | M4: =IFERROR(IF(Vi_SIM_Mobile[[#This Row],[Purchase Date]]="","NA",EDATE(Vi_SIM_Mobile[[#This Row],[Purchase Date]],12)),"NA") -> 46265 | N4: Chinmay Mobile Shopee | O4: 352456889188866 | P4: 354076819188865 | Q4: In-build | R4: Nano SIM | S4: 89910276709000963907 | U4: Activated
A5: =ROW()-ROW(Vi_SIM_Mobile[[#Headers],[Sr. No.]]) -> 4 | B5: 9371091016 | C5: 724 | D5: =IF(Vi_SIM_Mobile[[#This Row],[Employee Code]]=0,"-",IFERROR(IF(INDEX('EMP Info'!$B:$B, MATCH(TEXT(Vi_SIM_Mobile[[#This Row],[Employee Code]],"00000"), 'EMP Info'!$A:$A, 0))=0,"",INDEX('EMP Info'!$B:$B, MATCH(TEXT(Vi_SIM_Mobile[[#This Row],[Employee Code]],"00000"), 'EMP Info'!$A:$A, 0))),IFERROR(VLOOKUP(TEXT(Vi_SIM_Mobile[[#This Row],[Employee Code]],"00000"), 'EMP Info'!$A:$D, 2, FALSE) & " (" & VLOOKUP(TEXT(Vi_SIM_Mobile[[#This Row],[Employee Code]],"00000"), 'EMP Info'!$A:$D,4, FALSE) & ")",""))) -> Jitendra Balkrushna Navarkar | E5: =IF(Vi_SIM_Mobile[[#This Row],[Employee Code]]=0,"-",IFERROR(IF(INDEX('EMP Info'!$C:$C, MATCH(TEXT(Vi_SIM_Mobile[[#This Row],[Employee Code]],"00000"), 'EMP Info'!$A:$A, 0))=0,"",INDEX('EMP Info'!$C:$C, MATCH(TEXT(Vi_SIM_Mobile[[#This Row],[Employee Code]],"00000"), 'EMP Info'!$A:$A, 0))),IFERROR(VLOOKUP(TEXT(Vi_SIM_Mobile[[#This Row],[Employee Code]],"00000"), 'EMP Info'!$A:$D, 2, FALSE) & " (" & VLOOKUP(TEXT(Vi_SIM_Mobile[[#This Row],[Employee Code]],"00000"), 'EMP Info'!$A:$D,4, FALSE) & ")",""))) -> PD Lab | F5: Self | G5: Manish Gordhanbhai Tilala | H5: Production | I5: Smartphone | J5: Samsung A16 | K5: 45900 | L5: =IFERROR(IF(Vi_SIM_Mobile[[#This Row],[Warranty Date]]<TODAY(), "Out of Warranty", IF(Vi_SIM_Mobile[[#This Row],[Warranty Date]]-TODAY()<=30, "Expiring Soon", "In Warranty")),"-") -> Out of Warranty | M5: =IFERROR(IF(Vi_SIM_Mobile[[#This Row],[Purchase Date]]="","NA",EDATE(Vi_SIM_Mobile[[#This Row],[Purchase Date]],12)),"NA") -> 46265 | N5: Chinmay Mobile Shopee | O5: 352456889241582 | P5: 354076819241581 | Q5: In-build | R5: Nano SIM | S5: 89910276709000963683 | U5: Activated
A6: =ROW()-ROW(Vi_SIM_Mobile[[#Headers],[Sr. No.]]) -> 5 | B6: 9371091017 | C6: 399 | D6: =IF(Vi_SIM_Mobile[[#This Row],[Employee Code]]=0,"-",IFERROR(IF(INDEX('EMP Info'!$B:$B, MATCH(TEXT(Vi_SIM_Mobile[[#This Row],[Employee Code]],"00000"), 'EMP Info'!$A:$A, 0))=0,"",INDEX('EMP Info'!$B:$B, MATCH(TEXT(Vi_SIM_Mobile[[#This Row],[Employee Code]],"00000"), 'EMP Info'!$A:$A, 0))),IFERROR(VLOOKUP(TEXT(Vi_SIM_Mobile[[#This Row],[Employee Code]],"00000"), 'EMP Info'!$A:$D, 2, FALSE) & " (" & VLOOKUP(TEXT(Vi_SIM_Mobile[[#This Row],[Employee Code]],"00000"), 'EMP Info'!$A:$D,4, FALSE) & ")",""))) -> Sangram Shrikant Dhavane | E6: =IF(Vi_SIM_Mobile[[#This Row],[Employee Code]]=0,"-",IFERROR(IF(INDEX('EMP Info'!$C:$C, MATCH(TEXT(Vi_SIM_Mobile[[#This Row],[Employee Code]],"00000"), 'EMP Info'!$A:$A, 0))=0,"",INDEX('EMP Info'!$C:$C, MATCH(TEXT(Vi_SIM_Mobile[[#This Row],[Employee Code]],"00000"), 'EMP Info'!$A:$A, 0))),IFERROR(VLOOKUP(TEXT(Vi_SIM_Mobile[[#This Row],[Employee Code]],"00000"), 'EMP Info'!$A:$D, 2, FALSE) & " (" & VLOOKUP(TEXT(Vi_SIM_Mobile[[#This Row],[Employee Code]],"00000"), 'EMP Info'!$A:$D,4, FALSE) & ")",""))) -> Store | F6: E16 Engineering Store | G6: - | H6: - | I6: Basic Keypad Phone | J6: HMD 105 4G | K6: 45826 | L6: =IFERROR(IF(Vi_SIM_Mobile[[#This Row],[Warranty Date]]<TODAY(), "Out of Warranty", IF(Vi_SIM_Mobile[[#This Row],[Warranty Date]]-TODAY()<=30, "Expiring Soon", "In Warranty")),"-") -> Out of Warranty | M6: =IFERROR(IF(Vi_SIM_Mobile[[#This Row],[Purchase Date]]="","NA",EDATE(Vi_SIM_Mobile[[#This Row],[Purchase Date]],12)),"NA") -> 46191 | N6: Chinmay Mobile Shopee | O6: 359926420836812 | P6: 359926425836817 | Q6: UA01000911003253240110377 | R6: Nano SIM | S6: 89910276709000962545 | U6: Activated
A7: =ROW()-ROW(Vi_SIM_Mobile[[#Headers],[Sr. No.]]) -> 6 | B7: 9371091018 | C7: 0 | D7: =IF(Vi_SIM_Mobile[[#This Row],[Employee Code]]=0,"-",IFERROR(IF(INDEX('EMP Info'!$B:$B, MATCH(TEXT(Vi_SIM_Mobile[[#This Row],[Employee Code]],"00000"), 'EMP Info'!$A:$A, 0))=0,"",INDEX('EMP Info'!$B:$B, MATCH(TEXT(Vi_SIM_Mobile[[#This Row],[Employee Code]],"00000"), 'EMP Info'!$A:$A, 0))),IFERROR(VLOOKUP(TEXT(Vi_SIM_Mobile[[#This Row],[Employee Code]],"00000"), 'EMP Info'!$A:$D, 2, FALSE) & " (" & VLOOKUP(TEXT(Vi_SIM_Mobile[[#This Row],[Employee Code]],"00000"), 'EMP Info'!$A:$D,4, FALSE) & ")",""))) -> - | E7: =IF(Vi_SIM_Mobile[[#This Row],[Employee Code]]=0,"-",IFERROR(IF(INDEX('EMP Info'!$C:$C, MATCH(TEXT(Vi_SIM_Mobile[[#This Row],[Employee Code]],"00000"), 'EMP Info'!$A:$A, 0))=0,"",INDEX('EMP Info'!$C:$C, MATCH(TEXT(Vi_SIM_Mobile[[#This Row],[Employee Code]],"00000"), 'EMP Info'!$A:$A, 0))),IFERROR(VLOOKUP(TEXT(Vi_SIM_Mobile[[#This Row],[Employee Code]],"00000"), 'EMP Info'!$A:$D, 2, FALSE) & " (" & VLOOKUP(TEXT(Vi_SIM_Mobile[[#This Row],[Employee Code]],"00000"), 'EMP Info'!$A:$D,4, FALSE) & ")",""))) -> - | F7: - | G7: Shahnawaz Ahmad Nadaf | H7: Maintenance | I7: Basic Keypad Phone | J7: HMD 105 4G | K7: 45787 | L7: =IFERROR(IF(Vi_SIM_Mobile[[#This Row],[Warranty Date]]<TODAY(), "Out of Warranty", IF(Vi_SIM_Mobile[[#This Row],[Warranty Date]]-TODAY()<=30, "Expiring Soon", "In Warranty")),"-") -> Out of Warranty | M7: =IFERROR(IF(Vi_SIM_Mobile[[#This Row],[Purchase Date]]="","NA",EDATE(Vi_SIM_Mobile[[#This Row],[Purchase Date]],12)),"NA") -> 46152 | N7: Chinmay Mobile Shopee | O7: 359926420135553 | P7: 359926425135558 | Q7: UA0100091100324A090155735 | R7: Nano SIM | S7: 89910276709000962867 | U7: Activated
A8: =ROW()-ROW(Vi_SIM_Mobile[[#Headers],[Sr. No.]]) -> 7 | B8: 9371091019 | C8: 603 | D8: =IF(Vi_SIM_Mobile[[#This Row],[Employee Code]]=0,"-",IFERROR(IF(INDEX('EMP Info'!$B:$B, MATCH(TEXT(Vi_SIM_Mobile[[#This Row],[Employee Code]],"00000"), 'EMP Info'!$A:$A, 0))=0,"",INDEX('EMP Info'!$B:$B, MATCH(TEXT(Vi_SIM_Mobile[[#This Row],[Employee Code]],"00000"), 'EMP Info'!$A:$A, 0))),IFERROR(VLOOKUP(TEXT(Vi_SIM_Mobile[[#This Row],[Employee Code]],"00000"), 'EMP Info'!$A:$D, 2, FALSE) & " (" & VLOOKUP(TEXT(Vi_SIM_Mobile[[#This Row],[Employee Code]],"00000"), 'EMP Info'!$A:$D,4, FALSE) & ")",""))) -> Dattatray Deepak Chavan | E8: =IF(Vi_SIM_Mobile[[#This Row],[Employee Code]]=0,"-",IFERROR(IF(INDEX('EMP Info'!$C:$C, MATCH(TEXT(Vi_SIM_Mobile[[#This Row],[Employee Code]],"00000"), 'EMP Info'!$A:$A, 0))=0,"",INDEX('EMP Info'!$C:$C, MATCH(TEXT(Vi_SIM_Mobile[[#This Row],[Employee Code]],"00000"), 'EMP Info'!$A:$A, 0))),IFERROR(VLOOKUP(TEXT(Vi_SIM_Mobile[[#This Row],[Employee Code]],"00000"), 'EMP Info'!$A:$D, 2, FALSE) & " (" & VLOOKUP(TEXT(Vi_SIM_Mobile[[#This Row],[Employee Code]],"00000"), 'EMP Info'!$A:$D,4, FALSE) & ")",""))) -> Maintenance | F8: Self | G8: - | H8: - | I8: Smartphone | J8: Motorola Moto G85 5G | K8: 45815 | L8: =IFERROR(IF(Vi_SIM_Mobile[[#This Row],[Warranty Date]]<TODAY(), "Out of Warranty", IF(Vi_SIM_Mobile[[#This Row],[Warranty Date]]-TODAY()<=30, "Expiring Soon", "In Warranty")),"-") -> Out of Warranty | M8: =IFERROR(IF(Vi_SIM_Mobile[[#This Row],[Purchase Date]]="","NA",EDATE(Vi_SIM_Mobile[[#This Row],[Purchase Date]],12)),"NA") -> 46180 | O8: 350794154538510 / 10 | P8: 350794154538528 / 10 | R8: Nano SIM | S8: 89910276709000295367 | U8: Activated
A9: =ROW()-ROW(Vi_SIM_Mobile[[#Headers],[Sr. No.]]) -> 8 | B9: 9371091035 | C9: 679 | D9: =IF(Vi_SIM_Mobile[[#This Row],[Employee Code]]=0,"-",IFERROR(IF(INDEX('EMP Info'!$B:$B, MATCH(TEXT(Vi_SIM_Mobile[[#This Row],[Employee Code]],"00000"), 'EMP Info'!$A:$A, 0))=0,"",INDEX('EMP Info'!$B:$B, MATCH(TEXT(Vi_SIM_Mobile[[#This Row],[Employee Code]],"00000"), 'EMP Info'!$A:$A, 0))),IFERROR(VLOOKUP(TEXT(Vi_SIM_Mobile[[#This Row],[Employee Code]],"00000"), 'EMP Info'!$A:$D, 2, FALSE) & " (" & VLOOKUP(TEXT(Vi_SIM_Mobile[[#This Row],[Employee Code]],"00000"), 'EMP Info'!$A:$D,4, FALSE) & ")",""))) -> Nagesh Sharanappa Gangade | E9: =IF(Vi_SIM_Mobile[[#This Row],[Employee Code]]=0,"-",IFERROR(IF(INDEX('EMP Info'!$C:$C, MATCH(TEXT(Vi_SIM_Mobile[[#This Row],[Employee Code]],"00000"), 'EMP Info'!$A:$A, 0))=0,"",INDEX('EMP Info'!$C:$C, MATCH(TEXT(Vi_SIM_Mobile[[#This Row],[Employee Code]],"00000"), 'EMP Info'!$A:$A, 0))),IFERROR(VLOOKUP(TEXT(Vi_SIM_Mobile[[#This Row],[Employee Code]],"00000"), 'EMP Info'!$A:$D, 2, FALSE) & " (" & VLOOKUP(TEXT(Vi_SIM_Mobile[[#This Row],[Employee Code]],"00000"), 'EMP Info'!$A:$D,4, FALSE) & ")",""))) -> Instrument | F9: Self | G9: - | H9: - | I9: Basic Keypad Phone | J9: HMD 105 4G | K9: 45965 | L9: =IFERROR(IF(Vi_SIM_Mobile[[#This Row],[Warranty Date]]<TODAY(), "Out of Warranty", IF(Vi_SIM_Mobile[[#This Row],[Warranty Date]]-TODAY()<=30, "Expiring Soon", "In Warranty")),"-") -> In Warranty | M9: =IFERROR(IF(Vi_SIM_Mobile[[#This Row],[Purchase Date]]="","NA",EDATE(Vi_SIM_Mobile[[#This Row],[Purchase Date]],12)),"NA") -> 46330 | N9: Chinmay Mobile Shopee | O9: 359926420830104 | P9: 359926425830109 | Q9: FF040100090200124920AS03575 | R9: Nano SIM | S9: 89910273909029468267 | U9: Activated | V9: Type C Charger No.: BHCIN27545372929
A10: =ROW()-ROW(Vi_SIM_Mobile[[#Headers],[Sr. No.]]) -> 9 | B10: 9371091053 | C10: 721 | D10: =IF(Vi_SIM_Mobile[[#This Row],[Employee Code]]=0,"-",IFERROR(IF(INDEX('EMP Info'!$B:$B, MATCH(TEXT(Vi_SIM_Mobile[[#This Row],[Employee Code]],"00000"), 'EMP Info'!$A:$A, 0))=0,"",INDEX('EMP Info'!$B:$B, MATCH(TEXT(Vi_SIM_Mobile[[#This Row],[Employee Code]],"00000"), 'EMP Info'!$A:$A, 0))),IFERROR(VLOOKUP(TEXT(Vi_SIM_Mobile[[#This Row],[Employee Code]],"00000"), 'EMP Info'!$A:$D, 2, FALSE) & " (" & VLOOKUP(TEXT(Vi_SIM_Mobile[[#This Row],[Employee Code]],"00000"), 'EMP Info'!$A:$D,4, FALSE) & ")",""))) -> Sunil Sanjay Chanmal | E10: =IF(Vi_SIM_Mobile[[#This Row],[Employee Code]]=0,"-",IFERROR(IF(INDEX('EMP Info'!$C:$C, MATCH(TEXT(Vi_SIM_Mobile[[#This Row],[Employee Code]],"00000"), 'EMP Info'!$A:$A, 0))=0,"",INDEX('EMP Info'!$C:$C, MATCH(TEXT(Vi_SIM_Mobile[[#This Row],[Employee Code]],"00000"), 'EMP Info'!$A:$A, 0))),IFERROR(VLOOKUP(TEXT(Vi_SIM_Mobile[[#This Row],[Employee Code]],"00000"), 'EMP Info'!$A:$D, 2, FALSE) & " (" & VLOOKUP(TEXT(Vi_SIM_Mobile[[#This Row],[Employee Code]],"00000"), 'EMP Info'!$A:$D,4, FALSE) & ")",""))) -> Maintenance | F10: Self | G10: - | H10: - | K10: 46049 | L10: =IFERROR(IF(Vi_SIM_Mobile[[#This Row],[Warranty Date]]<TODAY(), "Out of Warranty", IF(Vi_SIM_Mobile[[#This Row],[Warranty Date]]-TODAY()<=30, "Expiring Soon", "In Warranty")),"-") -> In Warranty | M10: =IFERROR(IF(Vi_SIM_Mobile[[#This Row],[Purchase Date]]="","NA",EDATE(Vi_SIM_Mobile[[#This Row],[Purchase Date]],12)),"NA") -> 46414 | N10: Amazon Online | O10: 359926420374913 | P10: 359926425374918 | Q10: UA0100091100324A090191271 | R10: Nano SIM | S10: 89910273909029467517 | U10: Activated | V10: Type C Charger No.: BHCIN27544CE29D6
A11: =ROW()-ROW(Vi_SIM_Mobile[[#Headers],[Sr. No.]]) -> 10 | B11: 9371091062 | C11: 407 | D11: =IF(Vi_SIM_Mobile[[#This Row],[Employee Code]]=0,"-",IFERROR(IF(INDEX('EMP Info'!$B:$B, MATCH(TEXT(Vi_SIM_Mobile[[#This Row],[Employee Code]],"00000"), 'EMP Info'!$A:$A, 0))=0,"",INDEX('EMP Info'!$B:$B, MATCH(TEXT(Vi_SIM_Mobile[[#This Row],[Employee Code]],"00000"), 'EMP Info'!$A:$A, 0))),IFERROR(VLOOKUP(TEXT(Vi_SIM_Mobile[[#This Row],[Employee Code]],"00000"), 'EMP Info'!$A:$D, 2, FALSE) & " (" & VLOOKUP(TEXT(Vi_SIM_Mobile[[#This Row],[Employee Code]],"00000"), 'EMP Info'!$A:$D,4, FALSE) & ")",""))) -> Vijaykumar Bhimashankar Gurao | E11: =IF(Vi_SIM_Mobile[[#This Row],[Employee Code]]=0,"-",IFERROR(IF(INDEX('EMP Info'!$C:$C, MATCH(TEXT(Vi_SIM_Mobile[[#This Row],[Employee Code]],"00000"), 'EMP Info'!$A:$A, 0))=0,"",INDEX('EMP Info'!$C:$C, MATCH(TEXT(Vi_SIM_Mobile[[#This Row],[Employee Code]],"00000"), 'EMP Info'!$A:$A, 0))),IFERROR(VLOOKUP(TEXT(Vi_SIM_Mobile[[#This Row],[Employee Code]],"00000"), 'EMP Info'!$A:$D, 2, FALSE) & " (" & VLOOKUP(TEXT(Vi_SIM_Mobile[[#This Row],[Employee Code]],"00000"), 'EMP Info'!$A:$D,4, FALSE) & ")",""))) -> Maintenance | F11: Self | G11: - | H11: - | I11: Basic Keypad Phone | J11: HMD 105 4G | K11: 45961 | L11: =IFERROR(IF(Vi_SIM_Mobile[[#This Row],[Warranty Date]]<TODAY(), "Out of Warranty", IF(Vi_SIM_Mobile[[#This Row],[Warranty Date]]-TODAY()<=30, "Expiring Soon", "In Warranty")),"-") -> In Warranty | M11: =IFERROR(IF(Vi_SIM_Mobile[[#This Row],[Purchase Date]]="","NA",EDATE(Vi_SIM_Mobile[[#This Row],[Purchase Date]],12)),"NA") -> 46326 | N11: Chinmay Mobile Shopee | O11: 359926421187876 | P11: 359926426187871 | Q11: UA01000911003254190118288 | R11: Nano SIM | S11: 89910273909029468275 | U11: Activated
A12: =ROW()-ROW(Vi_SIM_Mobile[[#Headers],[Sr. No.]]) -> 11 | B12: 9371091068 | C12: 714 | D12: =IF(Vi_SIM_Mobile[[#This Row],[Employee Code]]=0,"-",IFERROR(IF(INDEX('EMP Info'!$B:$B, MATCH(TEXT(Vi_SIM_Mobile[[#This Row],[Employee Code]],"00000"), 'EMP Info'!$A:$A, 0))=0,"",INDEX('EMP Info'!$B:$B, MATCH(TEXT(Vi_SIM_Mobile[[#This Row],[Employee Code]],"00000"), 'EMP Info'!$A:$A, 0))),IFERROR(VLOOKUP(TEXT(Vi_SIM_Mobile[[#This Row],[Employee Code]],"00000"), 'EMP Info'!$A:$D, 2, FALSE) & " (" & VLOOKUP(TEXT(Vi_SIM_Mobile[[#This Row],[Employee Code]],"00000"), 'EMP Info'!$A:$D,4, FALSE) & ")",""))) -> Sushant Popat Masane | E12: =IF(Vi_SIM_Mobile[[#This Row],[Employee Code]]=0,"-",IFERROR(IF(INDEX('EMP Info'!$C:$C, MATCH(TEXT(Vi_SIM_Mobile[[#This Row],[Employee Code]],"00000"), 'EMP Info'!$A:$A, 0))=0,"",INDEX('EMP Info'!$C:$C, MATCH(TEXT(Vi_SIM_Mobile[[#This Row],[Employee Code]],"00000"), 'EMP Info'!$A:$A, 0))),IFERROR(VLOOKUP(TEXT(Vi_SIM_Mobile[[#This Row],[Employee Code]],"00000"), 'EMP Info'!$A:$D, 2, FALSE) & " (" & VLOOKUP(TEXT(Vi_SIM_Mobile[[#This Row],[Employee Code]],"00000"), 'EMP Info'!$A:$D,4, FALSE) & ")",""))) -> Store | F12: Self | G12: - | H12: - | I12: Smartphone | J12: Vivo Y29 5G | K12: 45926 | L12: =IFERROR(IF(Vi_SIM_Mobile[[#This Row],[Warranty Date]]<TODAY(), "Out of Warranty", IF(Vi_SIM_Mobile[[#This Row],[Warranty Date]]-TODAY()<=30, "Expiring Soon", "In Warranty")),"-") -> Expiring Soon | M12: =IFERROR(IF(Vi_SIM_Mobile[[#This Row],[Purchase Date]]="","NA",EDATE(Vi_SIM_Mobile[[#This Row],[Purchase Date]],12)),"NA") -> 46291 | N12: Chinmay Mobile Shopee | O12: 863439078347164 | P12: 863439078347172 | Q12: 7245246692793083456 | R12: Nano SIM | S12: 89910273909029467525 | U12: Activated
A13: =ROW()-ROW(Vi_SIM_Mobile[[#Headers],[Sr. No.]]) -> 12 | B13: 9371091073 | C13: 0 | D13: =IF(Vi_SIM_Mobile[[#This Row],[Employee Code]]=0,"-",IFERROR(IF(INDEX('EMP Info'!$B:$B, MATCH(TEXT(Vi_SIM_Mobile[[#This Row],[Employee Code]],"00000"), 'EMP Info'!$A:$A, 0))=0,"",INDEX('EMP Info'!$B:$B, MATCH(TEXT(Vi_SIM_Mobile[[#This Row],[Employee Code]],"00000"), 'EMP Info'!$A:$A, 0))),IFERROR(VLOOKUP(TEXT(Vi_SIM_Mobile[[#This Row],[Employee Code]],"00000"), 'EMP Info'!$A:$D, 2, FALSE) & " (" & VLOOKUP(TEXT(Vi_SIM_Mobile[[#This Row],[Employee Code]],"00000"), 'EMP Info'!$A:$D,4, FALSE) & ")",""))) -> - | E13: =IF(Vi_SIM_Mobile[[#This Row],[Employee Code]]=0,"-",IFERROR(IF(INDEX('EMP Info'!$C:$C, MATCH(TEXT(Vi_SIM_Mobile[[#This Row],[Employee Code]],"00000"), 'EMP Info'!$A:$A, 0))=0,"",INDEX('EMP Info'!$C:$C, MATCH(TEXT(Vi_SIM_Mobile[[#This Row],[Employee Code]],"00000"), 'EMP Info'!$A:$A, 0))),IFERROR(VLOOKUP(TEXT(Vi_SIM_Mobile[[#This Row],[Employee Code]],"00000"), 'EMP Info'!$A:$D, 2, FALSE) & " (" & VLOOKUP(TEXT(Vi_SIM_Mobile[[#This Row],[Employee Code]],"00000"), 'EMP Info'!$A:$D,4, FALSE) & ")",""))) -> - | F13: Self | L13: =IFERROR(IF(Vi_SIM_Mobile[[#This Row],[Warranty Date]]<TODAY(), "Out of Warranty", IF(Vi_SIM_Mobile[[#This Row],[Warranty Date]]-TODAY()<=30, "Expiring Soon", "In Warranty")),"-") -> - | M13: =IFERROR(IF(Vi_SIM_Mobile[[#This Row],[Purchase Date]]="","NA",EDATE(Vi_SIM_Mobile[[#This Row],[Purchase Date]],12)),"NA") -> NA | S13: 89910273909029467533 | U13: Activated
A14: =ROW()-ROW(Vi_SIM_Mobile[[#Headers],[Sr. No.]]) -> 13 | B14: 9371091088 | C14: 652 | D14: =IF(Vi_SIM_Mobile[[#This Row],[Employee Code]]=0,"-",IFERROR(IF(INDEX('EMP Info'!$B:$B, MATCH(TEXT(Vi_SIM_Mobile[[#This Row],[Employee Code]],"00000"), 'EMP Info'!$A:$A, 0))=0,"",INDEX('EMP Info'!$B:$B, MATCH(TEXT(Vi_SIM_Mobile[[#This Row],[Employee Code]],"00000"), 'EMP Info'!$A:$A, 0))),IFERROR(VLOOKUP(TEXT(Vi_SIM_Mobile[[#This Row],[Employee Code]],"00000"), 'EMP Info'!$A:$D, 2, FALSE) & " (" & VLOOKUP(TEXT(Vi_SIM_Mobile[[#This Row],[Employee Code]],"00000"), 'EMP Info'!$A:$D,4, FALSE) & ")",""))) -> Vishvajit Shivdas Nalawade | E14: =IF(Vi_SIM_Mobile[[#This Row],[Employee Code]]=0,"-",IFERROR(IF(INDEX('EMP Info'!$C:$C, MATCH(TEXT(Vi_SIM_Mobile[[#This Row],[Employee Code]],"00000"), 'EMP Info'!$A:$A, 0))=0,"",INDEX('EMP Info'!$C:$C, MATCH(TEXT(Vi_SIM_Mobile[[#This Row],[Employee Code]],"00000"), 'EMP Info'!$A:$A, 0))),IFERROR(VLOOKUP(TEXT(Vi_SIM_Mobile[[#This Row],[Employee Code]],"00000"), 'EMP Info'!$A:$D, 2, FALSE) & " (" & VLOOKUP(TEXT(Vi_SIM_Mobile[[#This Row],[Employee Code]],"00000"), 'EMP Info'!$A:$D,4, FALSE) & ")",""))) -> Technical Services | F14: Self | G14: - | H14: - | I14: Smartphone | J14: Samsung A16 | K14: 45723 | L14: =IFERROR(IF(Vi_SIM_Mobile[[#This Row],[Warranty Date]]<TODAY(), "Out of Warranty", IF(Vi_SIM_Mobile[[#This Row],[Warranty Date]]-TODAY()<=30, "Expiring Soon", "In Warranty")),"-") -> Out of Warranty | M14: =IFERROR(IF(Vi_SIM_Mobile[[#This Row],[Purchase Date]]="","NA",EDATE(Vi_SIM_Mobile[[#This Row],[Purchase Date]],12)),"NA") -> 46088 | N14: Sapana Electronics | O14: 352456882167404 | P14: 354076812167403 | R14: Nano SIM | S14: 89910275109043671685 | U14: Activated
A15: =ROW()-ROW(Vi_SIM_Mobile[[#Headers],[Sr. No.]]) -> 14 | B15: 9371091634 | C15: 342 | D15: =IFERROR(IF(INDEX('EMP Info'!$B:$B, MATCH(TEXT(Vi_SIM_Mobile[[#This Row],[Employee Code]],"00000"), 'EMP Info'!$A:$A, 0))=0,"",INDEX('EMP Info'!$B:$B, MATCH(TEXT(Vi_SIM_Mobile[[#This Row],[Employee Code]],"00000"), 'EMP Info'!$A:$A, 0))),IFERROR(VLOOKUP(TEXT(Vi_SIM_Mobile[[#This Row],[Employee Code]],"00000"), 'EMP Info'!$A:$D, 2, FALSE) & " (" & VLOOKUP(TEXT(Vi_SIM_Mobile[[#This Row],[Employee Code]],"00000"), 'EMP Info'!$A:$D,4, FALSE) & ")","")) -> Amol Prakash Chaudhari | E15: =IFERROR(IF(INDEX('EMP Info'!$C:$C, MATCH(TEXT(Vi_SIM_Mobile[[#This Row],[Employee Code]],"00000"), 'EMP Info'!$A:$A, 0))=0,"",INDEX('EMP Info'!$C:$C, MATCH(TEXT(Vi_SIM_Mobile[[#This Row],[Employee Code]],"00000"), 'EMP Info'!$A:$A, 0))),IFERROR(VLOOKUP(TEXT(Vi_SIM_Mobile[[#This Row],[Employee Code]],"00000"), 'EMP Info'!$A:$D, 2, FALSE) & " (" & VLOOKUP(TEXT(Vi_SIM_Mobile[[#This Row],[Employee Code]],"00000"), 'EMP Info'!$A:$D,4, FALSE) & ")","")) -> Project | F15: Project Team | I15: Basic Keypad Phone | J15: HMD 105 4G | K15: 46049 | L15: =IFERROR(IF(Vi_SIM_Mobile[[#This Row],[Warranty Date]]<TODAY(), "Out of Warranty", IF(Vi_SIM_Mobile[[#This Row],[Warranty Date]]-TODAY()<=30, "Expiring Soon", "In Warranty")),"-") -> In Warranty | M15: =IFERROR(IF(Vi_SIM_Mobile[[#This Row],[Purchase Date]]="","NA",EDATE(Vi_SIM_Mobile[[#This Row],[Purchase Date]],12)),"NA") -> 46414 | N15: Amazon Online | O15: 359926420374913 | P15: 359926425374918 | Q15: UA0100091100324A090191271 | R15: Nano SIM | S15: 89910273909029663867 | U15: Activated | V15: Type C Charger No.: BHCIN27544CE29D6
A16: =ROW()-ROW(Vi_SIM_Mobile[[#Headers],[Sr. No.]]) -> 15 | B16: 9371091639 | C16: 106 | D16: =IFERROR(IF(INDEX('EMP Info'!$B:$B, MATCH(TEXT(Vi_SIM_Mobile[[#This Row],[Employee Code]],"00000"), 'EMP Info'!$A:$A, 0))=0,"",INDEX('EMP Info'!$B:$B, MATCH(TEXT(Vi_SIM_Mobile[[#This Row],[Employee Code]],"00000"), 'EMP Info'!$A:$A, 0))),IFERROR(VLOOKUP(TEXT(Vi_SIM_Mobile[[#This Row],[Employee Code]],"00000"), 'EMP Info'!$A:$D, 2, FALSE) & " (" & VLOOKUP(TEXT(Vi_SIM_Mobile[[#This Row],[Employee Code]],"00000"), 'EMP Info'!$A:$D,4, FALSE) & ")","")) -> Ganesh Vitthal Tadaka | E16: =IFERROR(IF(INDEX('EMP Info'!$C:$C, MATCH(TEXT(Vi_SIM_Mobile[[#This Row],[Employee Code]],"00000"), 'EMP Info'!$A:$A, 0))=0,"",INDEX('EMP Info'!$C:$C, MATCH(TEXT(Vi_SIM_Mobile[[#This Row],[Employee Code]],"00000"), 'EMP Info'!$A:$A, 0))),IFERROR(VLOOKUP(TEXT(Vi_SIM_Mobile[[#This Row],[Employee Code]],"00000"), 'EMP Info'!$A:$D, 2, FALSE) & " (" & VLOOKUP(TEXT(Vi_SIM_Mobile[[#This Row],[Employee Code]],"00000"), 'EMP Info'!$A:$D,4, FALSE) & ")","")) -> Production | F16: Tank Fram Area Team | G16: - | H16: - | I16: Basic Keypad Phone | J16: HMD 105 4G | K16: 46097 | L16: =IFERROR(IF(Vi_SIM_Mobile[[#This Row],[Warranty Date]]<TODAY(), "Out of Warranty", IF(Vi_SIM_Mobile[[#This Row],[Warranty Date]]-TODAY()<=30, "Expiring Soon", "In Warranty")),"-") -> In Warranty | M16: =IFERROR(IF(Vi_SIM_Mobile[[#This Row],[Purchase Date]]="","NA",EDATE(Vi_SIM_Mobile[[#This Row],[Purchase Date]],12)),"NA") -> 46462 | N16: Amazon Online | O16: 359926421685739 | P16: 359926426685734 | Q16: UA01000911003261180118245 | R16: Nano SIM | S16: 89910273909029663750 | U16: Activated | V16: Type C Charger
A17: =ROW()-ROW(Vi_SIM_Mobile[[#Headers],[Sr. No.]]) -> 16 | B17: 9371091641 | C17: 739 | D17: =IFERROR(IF(INDEX('EMP Info'!$B:$B, MATCH(TEXT(Vi_SIM_Mobile[[#This Row],[Employee Code]],"00000"), 'EMP Info'!$A:$A, 0))=0,"",INDEX('EMP Info'!$B:$B, MATCH(TEXT(Vi_SIM_Mobile[[#This Row],[Employee Code]],"00000"), 'EMP Info'!$A:$A, 0))),IFERROR(VLOOKUP(TEXT(Vi_SIM_Mobile[[#This Row],[Employee Code]],"00000"), 'EMP Info'!$A:$D, 2, FALSE) & " (" & VLOOKUP(TEXT(Vi_SIM_Mobile[[#This Row],[Employee Code]],"00000"), 'EMP Info'!$A:$D,4, FALSE) & ")","")) -> Rajendra Ambaji Ghodke | E17: =IFERROR(IF(INDEX('EMP Info'!$C:$C, MATCH(TEXT(Vi_SIM_Mobile[[#This Row],[Employee Code]],"00000"), 'EMP Info'!$A:$A, 0))=0,"",INDEX('EMP Info'!$C:$C, MATCH(TEXT(Vi_SIM_Mobile[[#This Row],[Employee Code]],"00000"), 'EMP Info'!$A:$A, 0))),IFERROR(VLOOKUP(TEXT(Vi_SIM_Mobile[[#This Row],[Employee Code]],"00000"), 'EMP Info'!$A:$D, 2, FALSE) & " (" & VLOOKUP(TEXT(Vi_SIM_Mobile[[#This Row],[Employee Code]],"00000"), 'EMP Info'!$A:$D,4, FALSE) & ")","")) -> Project | F17: Self | G17: - | H17: - | J17: Personal | L17: =IFERROR(IF(Vi_SIM_Mobile[[#This Row],[Warranty Date]]<TODAY(), "Out of Warranty", IF(Vi_SIM_Mobile[[#This Row],[Warranty Date]]-TODAY()<=30, "Expiring Soon", "In Warranty")),"-") -> - | M17: =IFERROR(IF(Vi_SIM_Mobile[[#This Row],[Purchase Date]]="","NA",EDATE(Vi_SIM_Mobile[[#This Row],[Purchase Date]],12)),"NA") -> NA | R17: Nano SIM | S17: 89910273909029660210 | U17: Activated | V17: Use of Personal Mobile Permission Received
A18: =ROW()-ROW(Vi_SIM_Mobile[[#Headers],[Sr. No.]]) -> 17 | B18: 9371091652 | C18: 737 | D18: =IFERROR(IF(INDEX('EMP Info'!$B:$B, MATCH(TEXT(Vi_SIM_Mobile[[#This Row],[Employee Code]],"00000"), 'EMP Info'!$A:$A, 0))=0,"",INDEX('EMP Info'!$B:$B, MATCH(TEXT(Vi_SIM_Mobile[[#This Row],[Employee Code]],"00000"), 'EMP Info'!$A:$A, 0))),IFERROR(VLOOKUP(TEXT(Vi_SIM_Mobile[[#This Row],[Employee Code]],"00000"), 'EMP Info'!$A:$D, 2, FALSE) & " (" & VLOOKUP(TEXT(Vi_SIM_Mobile[[#This Row],[Employee Code]],"00000"), 'EMP Info'!$A:$D,4, FALSE) & ")","")) -> Pradeep Vasantappa Daruwale | E18: =IFERROR(IF(INDEX('EMP Info'!$C:$C, MATCH(TEXT(Vi_SIM_Mobile[[#This Row],[Employee Code]],"00000"), 'EMP Info'!$A:$A, 0))=0,"",INDEX('EMP Info'!$C:$C, MATCH(TEXT(Vi_SIM_Mobile[[#This Row],[Employee Code]],"00000"), 'EMP Info'!$A:$A, 0))),IFERROR(VLOOKUP(TEXT(Vi_SIM_Mobile[[#This Row],[Employee Code]],"00000"), 'EMP Info'!$A:$D, 2, FALSE) & " (" & VLOOKUP(TEXT(Vi_SIM_Mobile[[#This Row],[Employee Code]],"00000"), 'EMP Info'!$A:$D,4, FALSE) & ")","")) -> Production | F18: Self | J18: Personal | L18: =IFERROR(IF(Vi_SIM_Mobile[[#This Row],[Warranty Date]]<TODAY(), "Out of Warranty", IF(Vi_SIM_Mobile[[#This Row],[Warranty Date]]-TODAY()<=30, "Expiring Soon", "In Warranty")),"-") -> - | M18: =IFERROR(IF(Vi_SIM_Mobile[[#This Row],[Purchase Date]]="","NA",EDATE(Vi_SIM_Mobile[[#This Row],[Purchase Date]],12)),"NA") -> NA | S18: 89910273909029663404 | U18: Activated | V18: Use of Personal Mobile Permission Received
A19: =ROW()-ROW(Vi_SIM_Mobile[[#Headers],[Sr. No.]]) -> 18 | B19: 9371091661 | C19: 0 | D19: =IFERROR(IF(INDEX('EMP Info'!$B:$B, MATCH(TEXT(Vi_SIM_Mobile[[#This Row],[Employee Code]],"00000"), 'EMP Info'!$A:$A, 0))=0,"",INDEX('EMP Info'!$B:$B, MATCH(TEXT(Vi_SIM_Mobile[[#This Row],[Employee Code]],"00000"), 'EMP Info'!$A:$A, 0))),IFERROR(VLOOKUP(TEXT(Vi_SIM_Mobile[[#This Row],[Employee Code]],"00000"), 'EMP Info'!$A:$D, 2, FALSE) & " (" & VLOOKUP(TEXT(Vi_SIM_Mobile[[#This Row],[Employee Code]],"00000"), 'EMP Info'!$A:$D,4, FALSE) & ")","")) | E19: =IFERROR(IF(INDEX('EMP Info'!$C:$C, MATCH(TEXT(Vi_SIM_Mobile[[#This Row],[Employee Code]],"00000"), 'EMP Info'!$A:$A, 0))=0,"",INDEX('EMP Info'!$C:$C, MATCH(TEXT(Vi_SIM_Mobile[[#This Row],[Employee Code]],"00000"), 'EMP Info'!$A:$A, 0))),IFERROR(VLOOKUP(TEXT(Vi_SIM_Mobile[[#This Row],[Employee Code]],"00000"), 'EMP Info'!$A:$D, 2, FALSE) & " (" & VLOOKUP(TEXT(Vi_SIM_Mobile[[#This Row],[Employee Code]],"00000"), 'EMP Info'!$A:$D,4, FALSE) & ")","")) | L19: =IFERROR(IF(Vi_SIM_Mobile[[#This Row],[Warranty Date]]<TODAY(), "Out of Warranty", IF(Vi_SIM_Mobile[[#This Row],[Warranty Date]]-TODAY()<=30, "Expiring Soon", "In Warranty")),"-") -> - | M19: =IFERROR(IF(Vi_SIM_Mobile[[#This Row],[Purchase Date]]="","NA",EDATE(Vi_SIM_Mobile[[#This Row],[Purchase Date]],12)),"NA") -> NA | S19: 89910276309000741419 | U19: Activated
A20: =ROW()-ROW(Vi_SIM_Mobile[[#Headers],[Sr. No.]]) -> 19 | B20: 9371091662 | C20: 653 | D20: =IFERROR(IF(INDEX('EMP Info'!$B:$B, MATCH(TEXT(Vi_SIM_Mobile[[#This Row],[Employee Code]],"00000"), 'EMP Info'!$A:$A, 0))=0,"",INDEX('EMP Info'!$B:$B, MATCH(TEXT(Vi_SIM_Mobile[[#This Row],[Employee Code]],"00000"), 'EMP Info'!$A:$A, 0))),IFERROR(VLOOKUP(TEXT(Vi_SIM_Mobile[[#This Row],[Employee Code]],"00000"), 'EMP Info'!$A:$D, 2, FALSE) & " (" & VLOOKUP(TEXT(Vi_SIM_Mobile[[#This Row],[Employee Code]],"00000"), 'EMP Info'!$A:$D,4, FALSE) & ")","")) -> Piyush Dhanrajji Kapse | E20: =IFERROR(IF(INDEX('EMP Info'!$C:$C, MATCH(TEXT(Vi_SIM_Mobile[[#This Row],[Employee Code]],"00000"), 'EMP Info'!$A:$A, 0))=0,"",INDEX('EMP Info'!$C:$C, MATCH(TEXT(Vi_SIM_Mobile[[#This Row],[Employee Code]],"00000"), 'EMP Info'!$A:$A, 0))),IFERROR(VLOOKUP(TEXT(Vi_SIM_Mobile[[#This Row],[Employee Code]],"00000"), 'EMP Info'!$A:$D, 2, FALSE) & " (" & VLOOKUP(TEXT(Vi_SIM_Mobile[[#This Row],[Employee Code]],"00000"), 'EMP Info'!$A:$D,4, FALSE) & ")","")) -> Production | F20: Self | G20: - | H20: - | I20: Smartphone | J20: Samsung M06 | L20: =IFERROR(IF(Vi_SIM_Mobile[[#This Row],[Warranty Date]]<TODAY(), "Out of Warranty", IF(Vi_SIM_Mobile[[#This Row],[Warranty Date]]-TODAY()<=30, "Expiring Soon", "In Warranty")),"-") -> - | M20: =IFERROR(IF(Vi_SIM_Mobile[[#This Row],[Purchase Date]]="","NA",EDATE(Vi_SIM_Mobile[[#This Row],[Purchase Date]],12)),"NA") -> NA | N20: Amazon Online | O20: 350160042629335 | P20: 351989662629335 | R20: Nano SIM | S20: 89910276309000741427 | U20: Activated | V20: Ambrane Type C to Type C Charger No.: C25J02512027437
A21: =ROW()-ROW(Vi_SIM_Mobile[[#Headers],[Sr. No.]]) -> 20 | B21: 9371091664 | C21: 723 | D21: =IFERROR(IF(INDEX('EMP Info'!$B:$B, MATCH(TEXT(Vi_SIM_Mobile[[#This Row],[Employee Code]],"00000"), 'EMP Info'!$A:$A, 0))=0,"",INDEX('EMP Info'!$B:$B, MATCH(TEXT(Vi_SIM_Mobile[[#This Row],[Employee Code]],"00000"), 'EMP Info'!$A:$A, 0))),IFERROR(VLOOKUP(TEXT(Vi_SIM_Mobile[[#This Row],[Employee Code]],"00000"), 'EMP Info'!$A:$D, 2, FALSE) & " (" & VLOOKUP(TEXT(Vi_SIM_Mobile[[#This Row],[Employee Code]],"00000"), 'EMP Info'!$A:$D,4, FALSE) & ")","")) -> Pravin Shantaram Deshmukh | E21: =IFERROR(IF(INDEX('EMP Info'!$C:$C, MATCH(TEXT(Vi_SIM_Mobile[[#This Row],[Employee Code]],"00000"), 'EMP Info'!$A:$A, 0))=0,"",INDEX('EMP Info'!$C:$C, MATCH(TEXT(Vi_SIM_Mobile[[#This Row],[Employee Code]],"00000"), 'EMP Info'!$A:$A, 0))),IFERROR(VLOOKUP(TEXT(Vi_SIM_Mobile[[#This Row],[Employee Code]],"00000"), 'EMP Info'!$A:$D, 2, FALSE) & " (" & VLOOKUP(TEXT(Vi_SIM_Mobile[[#This Row],[Employee Code]],"00000"), 'EMP Info'!$A:$D,4, FALSE) & ")","")) -> Engineering | F21: CT Auto Dosing System | G21: - | H21: - | I21: - | J21: - | K21: - | L21: =IFERROR(IF(Vi_SIM_Mobile[[#This Row],[Warranty Date]]<TODAY(), "Out of Warranty", IF(Vi_SIM_Mobile[[#This Row],[Warranty Date]]-TODAY()<=30, "Expiring Soon", "In Warranty")),"-") -> - | M21: =IFERROR(IF(Vi_SIM_Mobile[[#This Row],[Purchase Date]]="","NA",EDATE(Vi_SIM_Mobile[[#This Row],[Purchase Date]],12)),"NA") -> NA | N21: - | O21: - | P21: - | Q21: - | S21: 89910276309000741401 | U21: Activated
A22: =ROW()-ROW(Vi_SIM_Mobile[[#Headers],[Sr. No.]]) -> 21 | B22: 9371091667 | C22: 0 | D22: =IFERROR(IF(INDEX('EMP Info'!$B:$B, MATCH(TEXT(Vi_SIM_Mobile[[#This Row],[Employee Code]],"00000"), 'EMP Info'!$A:$A, 0))=0,"",INDEX('EMP Info'!$B:$B, MATCH(TEXT(Vi_SIM_Mobile[[#This Row],[Employee Code]],"00000"), 'EMP Info'!$A:$A, 0))),IFERROR(VLOOKUP(TEXT(Vi_SIM_Mobile[[#This Row],[Employee Code]],"00000"), 'EMP Info'!$A:$D, 2, FALSE) & " (" & VLOOKUP(TEXT(Vi_SIM_Mobile[[#This Row],[Employee Code]],"00000"), 'EMP Info'!$A:$D,4, FALSE) & ")","")) | E22: =IFERROR(IF(INDEX('EMP Info'!$C:$C, MATCH(TEXT(Vi_SIM_Mobile[[#This Row],[Employee Code]],"00000"), 'EMP Info'!$A:$A, 0))=0,"",INDEX('EMP Info'!$C:$C, MATCH(TEXT(Vi_SIM_Mobile[[#This Row],[Employee Code]],"00000"), 'EMP Info'!$A:$A, 0))),IFERROR(VLOOKUP(TEXT(Vi_SIM_Mobile[[#This Row],[Employee Code]],"00000"), 'EMP Info'!$A:$D, 2, FALSE) & " (" & VLOOKUP(TEXT(Vi_SIM_Mobile[[#This Row],[Employee Code]],"00000"), 'EMP Info'!$A:$D,4, FALSE) & ")","")) | L22: =IFERROR(IF(Vi_SIM_Mobile[[#This Row],[Warranty Date]]<TODAY(), "Out of Warranty", IF(Vi_SIM_Mobile[[#This Row],[Warranty Date]]-TODAY()<=30, "Expiring Soon", "In Warranty")),"-") -> - | M22: =IFERROR(IF(Vi_SIM_Mobile[[#This Row],[Purchase Date]]="","NA",EDATE(Vi_SIM_Mobile[[#This Row],[Purchase Date]],12)),"NA") -> NA | S22: 89910276309000741435 | U22: Activated
A23: =ROW()-ROW(Vi_SIM_Mobile[[#Headers],[Sr. No.]]) -> 22 | B23: 9371091669 | C23: 747 | D23: =IFERROR(IF(INDEX('EMP Info'!$B:$B, MATCH(TEXT(Vi_SIM_Mobile[[#This Row],[Employee Code]],"00000"), 'EMP Info'!$A:$A, 0))=0,"",INDEX('EMP Info'!$B:$B, MATCH(TEXT(Vi_SIM_Mobile[[#This Row],[Employee Code]],"00000"), 'EMP Info'!$A:$A, 0))),IFERROR(VLOOKUP(TEXT(Vi_SIM_Mobile[[#This Row],[Employee Code]],"00000"), 'EMP Info'!$A:$D, 2, FALSE) & " (" & VLOOKUP(TEXT(Vi_SIM_Mobile[[#This Row],[Employee Code]],"00000"), 'EMP Info'!$A:$D,4, FALSE) & ")","")) -> Tanaji Nagorao Kadam | E23: =IFERROR(IF(INDEX('EMP Info'!$C:$C, MATCH(TEXT(Vi_SIM_Mobile[[#This Row],[Employee Code]],"00000"), 'EMP Info'!$A:$A, 0))=0,"",INDEX('EMP Info'!$C:$C, MATCH(TEXT(Vi_SIM_Mobile[[#This Row],[Employee Code]],"00000"), 'EMP Info'!$A:$A, 0))),IFERROR(VLOOKUP(TEXT(Vi_SIM_Mobile[[#This Row],[Employee Code]],"00000"), 'EMP Info'!$A:$D, 2, FALSE) & " (" & VLOOKUP(TEXT(Vi_SIM_Mobile[[#This Row],[Employee Code]],"00000"), 'EMP Info'!$A:$D,4, FALSE) & ")","")) -> Technical Services | F23: Self | G23: - | H23: - | I23: Smartphone | J23: Personal | L23: =IFERROR(IF(Vi_SIM_Mobile[[#This Row],[Warranty Date]]<TODAY(), "Out of Warranty", IF(Vi_SIM_Mobile[[#This Row],[Warranty Date]]-TODAY()<=30, "Expiring Soon", "In Warranty")),"-") -> - | M23: =IFERROR(IF(Vi_SIM_Mobile[[#This Row],[Purchase Date]]="","NA",EDATE(Vi_SIM_Mobile[[#This Row],[Purchase Date]],12)),"NA") -> NA | R23: Nano SIM | S23: 89910276309000741443 | U23: Activated
A24: =ROW()-ROW(Vi_SIM_Mobile[[#Headers],[Sr. No.]]) -> 23 | B24: 9371091689 | C24: 106 | D24: =IFERROR(IF(INDEX('EMP Info'!$B:$B, MATCH(TEXT(Vi_SIM_Mobile[[#This Row],[Employee Code]],"00000"), 'EMP Info'!$A:$A, 0))=0,"",INDEX('EMP Info'!$B:$B, MATCH(TEXT(Vi_SIM_Mobile[[#This Row],[Employee Code]],"00000"), 'EMP Info'!$A:$A, 0))),IFERROR(VLOOKUP(TEXT(Vi_SIM_Mobile[[#This Row],[Employee Code]],"00000"), 'EMP Info'!$A:$D, 2, FALSE) & " (" & VLOOKUP(TEXT(Vi_SIM_Mobile[[#This Row],[Employee Code]],"00000"), 'EMP Info'!$A:$D,4, FALSE) & ")","")) -> Ganesh Vitthal Tadaka | E24: =IFERROR(IF(INDEX('EMP Info'!$C:$C, MATCH(TEXT(Vi_SIM_Mobile[[#This Row],[Employee Code]],"00000"), 'EMP Info'!$A:$A, 0))=0,"",INDEX('EMP Info'!$C:$C, MATCH(TEXT(Vi_SIM_Mobile[[#This Row],[Employee Code]],"00000"), 'EMP Info'!$A:$A, 0))),IFERROR(VLOOKUP(TEXT(Vi_SIM_Mobile[[#This Row],[Employee Code]],"00000"), 'EMP Info'!$A:$D, 2, FALSE) & " (" & VLOOKUP(TEXT(Vi_SIM_Mobile[[#This Row],[Employee Code]],"00000"), 'EMP Info'!$A:$D,4, FALSE) & ")","")) -> Production | F24: Self | G24: - | H24: - | I24: Smartphone | J24: Samsung M06 | K24: 46097 | L24: =IFERROR(IF(Vi_SIM_Mobile[[#This Row],[Warranty Date]]<TODAY(), "Out of Warranty", IF(Vi_SIM_Mobile[[#This Row],[Warranty Date]]-TODAY()<=30, "Expiring Soon", "In Warranty")),"-") -> In Warranty | M24: =IFERROR(IF(Vi_SIM_Mobile[[#This Row],[Purchase Date]]="","NA",EDATE(Vi_SIM_Mobile[[#This Row],[Purchase Date]],12)),"NA") -> 46462 | N24: Amazon Online | O24: 350160042628329 | P24: 351989662628329 | R24: Nano SIM | S24: 89910273909029663875 | U24: Activated | V24: Mobile Charger (Sr. No.: C25J02512027435), Mobile Back Cover
A25: =ROW()-ROW(Vi_SIM_Mobile[[#Headers],[Sr. No.]]) -> 24 | B25: 9371109124 | C25: 0 | D25: =IF(Vi_SIM_Mobile[[#This Row],[Employee Code]]=0,"-",IFERROR(IF(INDEX('EMP Info'!$B:$B, MATCH(TEXT(Vi_SIM_Mobile[[#This Row],[Employee Code]],"00000"), 'EMP Info'!$A:$A, 0))=0,"",INDEX('EMP Info'!$B:$B, MATCH(TEXT(Vi_SIM_Mobile[[#This Row],[Employee Code]],"00000"), 'EMP Info'!$A:$A, 0))),IFERROR(VLOOKUP(TEXT(Vi_SIM_Mobile[[#This Row],[Employee Code]],"00000"), 'EMP Info'!$A:$D, 2, FALSE) & " (" & VLOOKUP(TEXT(Vi_SIM_Mobile[[#This Row],[Employee Code]],"00000"), 'EMP Info'!$A:$D,4, FALSE) & ")",""))) -> - | E25: =IF(Vi_SIM_Mobile[[#This Row],[Employee Code]]=0,"-",IFERROR(IF(INDEX('EMP Info'!$C:$C, MATCH(TEXT(Vi_SIM_Mobile[[#This Row],[Employee Code]],"00000"), 'EMP Info'!$A:$A, 0))=0,"",INDEX('EMP Info'!$C:$C, MATCH(TEXT(Vi_SIM_Mobile[[#This Row],[Employee Code]],"00000"), 'EMP Info'!$A:$A, 0))),IFERROR(VLOOKUP(TEXT(Vi_SIM_Mobile[[#This Row],[Employee Code]],"00000"), 'EMP Info'!$A:$D, 2, FALSE) & " (" & VLOOKUP(TEXT(Vi_SIM_Mobile[[#This Row],[Employee Code]],"00000"), 'EMP Info'!$A:$D,4, FALSE) & ")",""))) -> - | F25: E20 Security Officer | I25: Basic Keypad Phone | J25: Nokia 105 | K25: 45680 | L25: =IFERROR(IF(Vi_SIM_Mobile[[#This Row],[Warranty Date]]<TODAY(), "Out of Warranty", IF(Vi_SIM_Mobile[[#This Row],[Warranty Date]]-TODAY()<=30, "Expiring Soon", "In Warranty")),"-") -> Out of Warranty | M25: =IFERROR(IF(Vi_SIM_Mobile[[#This Row],[Purchase Date]]="","NA",EDATE(Vi_SIM_Mobile[[#This Row],[Purchase Date]],12)),"NA") -> 46045 | O25: 356049420105949 | S25: 89910273501011454478 | U25: Activated
A26: =ROW()-ROW(Vi_SIM_Mobile[[#Headers],[Sr. No.]]) -> 25 | B26: 9371109125 | C26: 0 | D26: =IF(Vi_SIM_Mobile[[#This Row],[Employee Code]]=0,"-",IFERROR(IF(INDEX('EMP Info'!$B:$B, MATCH(TEXT(Vi_SIM_Mobile[[#This Row],[Employee Code]],"00000"), 'EMP Info'!$A:$A, 0))=0,"",INDEX('EMP Info'!$B:$B, MATCH(TEXT(Vi_SIM_Mobile[[#This Row],[Employee Code]],"00000"), 'EMP Info'!$A:$A, 0))),IFERROR(VLOOKUP(TEXT(Vi_SIM_Mobile[[#This Row],[Employee Code]],"00000"), 'EMP Info'!$A:$D, 2, FALSE) & " (" & VLOOKUP(TEXT(Vi_SIM_Mobile[[#This Row],[Employee Code]],"00000"), 'EMP Info'!$A:$D,4, FALSE) & ")",""))) -> - | E26: =IF(Vi_SIM_Mobile[[#This Row],[Employee Code]]=0,"-",IFERROR(IF(INDEX('EMP Info'!$C:$C, MATCH(TEXT(Vi_SIM_Mobile[[#This Row],[Employee Code]],"00000"), 'EMP Info'!$A:$A, 0))=0,"",INDEX('EMP Info'!$C:$C, MATCH(TEXT(Vi_SIM_Mobile[[#This Row],[Employee Code]],"00000"), 'EMP Info'!$A:$A, 0))),IFERROR(VLOOKUP(TEXT(Vi_SIM_Mobile[[#This Row],[Employee Code]],"00000"), 'EMP Info'!$A:$D, 2, FALSE) & " (" & VLOOKUP(TEXT(Vi_SIM_Mobile[[#This Row],[Employee Code]],"00000"), 'EMP Info'!$A:$D,4, FALSE) & ")",""))) -> - | F26: E DCS Room | I26: Basic Keypad Phone | J26: Nokia 105 | L26: =IFERROR(IF(Vi_SIM_Mobile[[#This Row],[Warranty Date]]<TODAY(), "Out of Warranty", IF(Vi_SIM_Mobile[[#This Row],[Warranty Date]]-TODAY()<=30, "Expiring Soon", "In Warranty")),"-") -> - | M26: =IFERROR(IF(Vi_SIM_Mobile[[#This Row],[Purchase Date]]="","NA",EDATE(Vi_SIM_Mobile[[#This Row],[Purchase Date]],12)),"NA") -> NA | S26: 89910274409014654889 | U26: Activated
A27: =ROW()-ROW(Vi_SIM_Mobile[[#Headers],[Sr. No.]]) -> 26 | B27: 9371109126 | C27: 0 | D27: =IF(Vi_SIM_Mobile[[#This Row],[Employee Code]]=0,"-",IFERROR(IF(INDEX('EMP Info'!$B:$B, MATCH(TEXT(Vi_SIM_Mobile[[#This Row],[Employee Code]],"00000"), 'EMP Info'!$A:$A, 0))=0,"",INDEX('EMP Info'!$B:$B, MATCH(TEXT(Vi_SIM_Mobile[[#This Row],[Employee Code]],"00000"), 'EMP Info'!$A:$A, 0))),IFERROR(VLOOKUP(TEXT(Vi_SIM_Mobile[[#This Row],[Employee Code]],"00000"), 'EMP Info'!$A:$D, 2, FALSE) & " (" & VLOOKUP(TEXT(Vi_SIM_Mobile[[#This Row],[Employee Code]],"00000"), 'EMP Info'!$A:$D,4, FALSE) & ")",""))) -> - | E27: =IF(Vi_SIM_Mobile[[#This Row],[Employee Code]]=0,"-",IFERROR(IF(INDEX('EMP Info'!$C:$C, MATCH(TEXT(Vi_SIM_Mobile[[#This Row],[Employee Code]],"00000"), 'EMP Info'!$A:$A, 0))=0,"",INDEX('EMP Info'!$C:$C, MATCH(TEXT(Vi_SIM_Mobile[[#This Row],[Employee Code]],"00000"), 'EMP Info'!$A:$A, 0))),IFERROR(VLOOKUP(TEXT(Vi_SIM_Mobile[[#This Row],[Employee Code]],"00000"), 'EMP Info'!$A:$D, 2, FALSE) & " (" & VLOOKUP(TEXT(Vi_SIM_Mobile[[#This Row],[Employee Code]],"00000"), 'EMP Info'!$A:$D,4, FALSE) & ")",""))) -> - | F27: E22 Boiler Control Room | I27: Basic Keypad Phone | J27: Nokia 105 | L27: =IFERROR(IF(Vi_SIM_Mobile[[#This Row],[Warranty Date]]<TODAY(), "Out of Warranty", IF(Vi_SIM_Mobile[[#This Row],[Warranty Date]]-TODAY()<=30, "Expiring Soon", "In Warranty")),"-") -> - | M27: =IFERROR(IF(Vi_SIM_Mobile[[#This Row],[Purchase Date]]="","NA",EDATE(Vi_SIM_Mobile[[#This Row],[Purchase Date]],12)),"NA") -> NA | S27: 89910274409014654897 | U27: Activated
A28: =ROW()-ROW(Vi_SIM_Mobile[[#Headers],[Sr. No.]]) -> 27 | B28: 9371109127 | C28: 383 | D28: =IF(Vi_SIM_Mobile[[#This Row],[Employee Code]]=0,"-",IFERROR(IF(INDEX('EMP Info'!$B:$B, MATCH(TEXT(Vi_SIM_Mobile[[#This Row],[Employee Code]],"00000"), 'EMP Info'!$A:$A, 0))=0,"",INDEX('EMP Info'!$B:$B, MATCH(TEXT(Vi_SIM_Mobile[[#This Row],[Employee Code]],"00000"), 'EMP Info'!$A:$A, 0))),IFERROR(VLOOKUP(TEXT(Vi_SIM_Mobile[[#This Row],[Employee Code]],"00000"), 'EMP Info'!$A:$D, 2, FALSE) & " (" & VLOOKUP(TEXT(Vi_SIM_Mobile[[#This Row],[Employee Code]],"00000"), 'EMP Info'!$A:$D,4, FALSE) & ")",""))) -> Siddeshwar Mahadev More | E28: =IF(Vi_SIM_Mobile[[#This Row],[Employee Code]]=0,"-",IFERROR(IF(INDEX('EMP Info'!$C:$C, MATCH(TEXT(Vi_SIM_Mobile[[#This Row],[Employee Code]],"00000"), 'EMP Info'!$A:$A, 0))=0,"",INDEX('EMP Info'!$C:$C, MATCH(TEXT(Vi_SIM_Mobile[[#This Row],[Employee Code]],"00000"), 'EMP Info'!$A:$A, 0))),IFERROR(VLOOKUP(TEXT(Vi_SIM_Mobile[[#This Row],[Employee Code]],"00000"), 'EMP Info'!$A:$D, 2, FALSE) & " (" & VLOOKUP(TEXT(Vi_SIM_Mobile[[#This Row],[Employee Code]],"00000"), 'EMP Info'!$A:$D,4, FALSE) & ")",""))) -> Utility | F28: Utility E 17 | I28: Basic Keypad Phone | J28: HMD 105 4G | K28: 46189 | L28: =IFERROR(IF(Vi_SIM_Mobile[[#This Row],[Warranty Date]]<TODAY(), "Out of Warranty", IF(Vi_SIM_Mobile[[#This Row],[Warranty Date]]-TODAY()<=30, "Expiring Soon", "In Warranty")),"-") -> In Warranty | M28: =IFERROR(IF(Vi_SIM_Mobile[[#This Row],[Purchase Date]]="","NA",EDATE(Vi_SIM_Mobile[[#This Row],[Purchase Date]],12)),"NA") -> 46554 | N28: Amazon Online | O28: 359926421564149 | P28: 359926426654144 | Q28: UA01000911003261180129599 | R28: Nano SIM | S28: 89910274409014654905 | U28: Activated | V28: Replaced with damaged Mobile (Damage mobile)
A29: =ROW()-ROW(Vi_SIM_Mobile[[#Headers],[Sr. No.]]) -> 28 | B29: 9371109128 | C29: 14 | D29: =IF(Vi_SIM_Mobile[[#This Row],[Employee Code]]=0,"-",IFERROR(IF(INDEX('EMP Info'!$B:$B, MATCH(TEXT(Vi_SIM_Mobile[[#This Row],[Employee Code]],"00000"), 'EMP Info'!$A:$A, 0))=0,"",INDEX('EMP Info'!$B:$B, MATCH(TEXT(Vi_SIM_Mobile[[#This Row],[Employee Code]],"00000"), 'EMP Info'!$A:$A, 0))),IFERROR(VLOOKUP(TEXT(Vi_SIM_Mobile[[#This Row],[Employee Code]],"00000"), 'EMP Info'!$A:$D, 2, FALSE) & " (" & VLOOKUP(TEXT(Vi_SIM_Mobile[[#This Row],[Employee Code]],"00000"), 'EMP Info'!$A:$D,4, FALSE) & ")",""))) -> Prashant Sukhdev Ingle | E29: =IF(Vi_SIM_Mobile[[#This Row],[Employee Code]]=0,"-",IFERROR(IF(INDEX('EMP Info'!$C:$C, MATCH(TEXT(Vi_SIM_Mobile[[#This Row],[Employee Code]],"00000"), 'EMP Info'!$A:$A, 0))=0,"",INDEX('EMP Info'!$C:$C, MATCH(TEXT(Vi_SIM_Mobile[[#This Row],[Employee Code]],"00000"), 'EMP Info'!$A:$A, 0))),IFERROR(VLOOKUP(TEXT(Vi_SIM_Mobile[[#This Row],[Employee Code]],"00000"), 'EMP Info'!$A:$D, 2, FALSE) & " (" & VLOOKUP(TEXT(Vi_SIM_Mobile[[#This Row],[Employee Code]],"00000"), 'EMP Info'!$A:$D,4, FALSE) & ")",""))) -> HR | I29: Basic Keypad Phone | J29: Nokia 105 | K29: 45572 | L29: =IFERROR(IF(Vi_SIM_Mobile[[#This Row],[Warranty Date]]<TODAY(), "Out of Warranty", IF(Vi_SIM_Mobile[[#This Row],[Warranty Date]]-TODAY()<=30, "Expiring Soon", "In Warranty")),"-") -> Out of Warranty | M29: =IFERROR(IF(Vi_SIM_Mobile[[#This Row],[Purchase Date]]="","NA",EDATE(Vi_SIM_Mobile[[#This Row],[Purchase Date]],12)),"NA") -> 45937 | S29: 89910274409014654913 | U29: Activated
A30: =ROW()-ROW(Vi_SIM_Mobile[[#Headers],[Sr. No.]]) -> 29 | B30: 9371109129 | C30: 0 | D30: E-18 Security Guard (Ramchandra Mote) | E30: Security | F30: E18 Security Main Gate | G30: E17 Security | H30: Security | I30: Basic Keypad Phone | J30: HMD 105 4G | K30: 45882 | L30: =IFERROR(IF(Vi_SIM_Mobile[[#This Row],[Warranty Date]]<TODAY(), "Out of Warranty", IF(Vi_SIM_Mobile[[#This Row],[Warranty Date]]-TODAY()<=30, "Expiring Soon", "In Warranty")),"-") -> Out of Warranty | M30: =IFERROR(IF(Vi_SIM_Mobile[[#This Row],[Purchase Date]]="","NA",EDATE(Vi_SIM_Mobile[[#This Row],[Purchase Date]],12)),"NA") -> 46247 | N30: Chinmay Mobile Shopee | O30: 359926420844295 | P30: 359926425844290 | Q30: UA01000911003253240102899 | R30: Nano SIM | S30: 89910274409014654996 | U30: Activated
A31: =ROW()-ROW(Vi_SIM_Mobile[[#Headers],[Sr. No.]]) -> 30 | B31: 9371109130 | C31: 302 | D31: =IF(Vi_SIM_Mobile[[#This Row],[Employee Code]]=0,"-",IFERROR(IF(INDEX('EMP Info'!$B:$B, MATCH(TEXT(Vi_SIM_Mobile[[#This Row],[Employee Code]],"00000"), 'EMP Info'!$A:$A, 0))=0,"",INDEX('EMP Info'!$B:$B, MATCH(TEXT(Vi_SIM_Mobile[[#This Row],[Employee Code]],"00000"), 'EMP Info'!$A:$A, 0))),IFERROR(VLOOKUP(TEXT(Vi_SIM_Mobile[[#This Row],[Employee Code]],"00000"), 'EMP Info'!$A:$D, 2, FALSE) & " (" & VLOOKUP(TEXT(Vi_SIM_Mobile[[#This Row],[Employee Code]],"00000"), 'EMP Info'!$A:$D,4, FALSE) & ")",""))) -> Pandurang Dagadu Ingale | E31: =IF(Vi_SIM_Mobile[[#This Row],[Employee Code]]=0,"-",IFERROR(IF(INDEX('EMP Info'!$C:$C, MATCH(TEXT(Vi_SIM_Mobile[[#This Row],[Employee Code]],"00000"), 'EMP Info'!$A:$A, 0))=0,"",INDEX('EMP Info'!$C:$C, MATCH(TEXT(Vi_SIM_Mobile[[#This Row],[Employee Code]],"00000"), 'EMP Info'!$A:$A, 0))),IFERROR(VLOOKUP(TEXT(Vi_SIM_Mobile[[#This Row],[Employee Code]],"00000"), 'EMP Info'!$A:$D, 2, FALSE) & " (" & VLOOKUP(TEXT(Vi_SIM_Mobile[[#This Row],[Employee Code]],"00000"), 'EMP Info'!$A:$D,4, FALSE) & ")",""))) -> Production | F31: A Block (Production) | I31: Basic Keypad Phone | J31: HMD 105 4G | K31: 45883 | L31: =IFERROR(IF(Vi_SIM_Mobile[[#This Row],[Warranty Date]]<TODAY(), "Out of Warranty", IF(Vi_SIM_Mobile[[#This Row],[Warranty Date]]-TODAY()<=30, "Expiring Soon", "In Warranty")),"-") -> Out of Warranty | M31: =IFERROR(IF(Vi_SIM_Mobile[[#This Row],[Purchase Date]]="","NA",EDATE(Vi_SIM_Mobile[[#This Row],[Purchase Date]],12)),"NA") -> 46248 | N31: Chinmay Mobile Shopee | O31: 359926420822051 | P31: 359926425822056 | Q31: UA01000911003253240129528 | R31: Nano SIM | S31: 89910274409014654921 | U31: Activated
A32: =ROW()-ROW(Vi_SIM_Mobile[[#Headers],[Sr. No.]]) -> 31 | B32: 9371109131 | C32: 0 | D32: =IF(Vi_SIM_Mobile[[#This Row],[Employee Code]]=0,"-",IFERROR(IF(INDEX('EMP Info'!$B:$B, MATCH(TEXT(Vi_SIM_Mobile[[#This Row],[Employee Code]],"00000"), 'EMP Info'!$A:$A, 0))=0,"",INDEX('EMP Info'!$B:$B, MATCH(TEXT(Vi_SIM_Mobile[[#This Row],[Employee Code]],"00000"), 'EMP Info'!$A:$A, 0))),IFERROR(VLOOKUP(TEXT(Vi_SIM_Mobile[[#This Row],[Employee Code]],"00000"), 'EMP Info'!$A:$D, 2, FALSE) & " (" & VLOOKUP(TEXT(Vi_SIM_Mobile[[#This Row],[Employee Code]],"00000"), 'EMP Info'!$A:$D,4, FALSE) & ")",""))) -> - | E32: =IF(Vi_SIM_Mobile[[#This Row],[Employee Code]]=0,"-",IFERROR(IF(INDEX('EMP Info'!$C:$C, MATCH(TEXT(Vi_SIM_Mobile[[#This Row],[Employee Code]],"00000"), 'EMP Info'!$A:$A, 0))=0,"",INDEX('EMP Info'!$C:$C, MATCH(TEXT(Vi_SIM_Mobile[[#This Row],[Employee Code]],"00000"), 'EMP Info'!$A:$A, 0))),IFERROR(VLOOKUP(TEXT(Vi_SIM_Mobile[[#This Row],[Employee Code]],"00000"), 'EMP Info'!$A:$D, 2, FALSE) & " (" & VLOOKUP(TEXT(Vi_SIM_Mobile[[#This Row],[Employee Code]],"00000"), 'EMP Info'!$A:$D,4, FALSE) & ")",""))) -> - | F32: B Block (Production) | I32: Basic Keypad Phone | J32: Nokia 105 | K32: 45546 | L32: =IFERROR(IF(Vi_SIM_Mobile[[#This Row],[Warranty Date]]<TODAY(), "Out of Warranty", IF(Vi_SIM_Mobile[[#This Row],[Warranty Date]]-TODAY()<=30, "Expiring Soon", "In Warranty")),"-") -> Out of Warranty | M32: =IFERROR(IF(Vi_SIM_Mobile[[#This Row],[Purchase Date]]="","NA",EDATE(Vi_SIM_Mobile[[#This Row],[Purchase Date]],12)),"NA") -> 45911 | S32: 89910274409014655092 | U32: Activated
A33: =ROW()-ROW(Vi_SIM_Mobile[[#Headers],[Sr. No.]]) -> 32 | B33: 9371109132 | C33: 0 | D33: =IF(Vi_SIM_Mobile[[#This Row],[Employee Code]]=0,"-",IFERROR(IF(INDEX('EMP Info'!$B:$B, MATCH(TEXT(Vi_SIM_Mobile[[#This Row],[Employee Code]],"00000"), 'EMP Info'!$A:$A, 0))=0,"",INDEX('EMP Info'!$B:$B, MATCH(TEXT(Vi_SIM_Mobile[[#This Row],[Employee Code]],"00000"), 'EMP Info'!$A:$A, 0))),IFERROR(VLOOKUP(TEXT(Vi_SIM_Mobile[[#This Row],[Employee Code]],"00000"), 'EMP Info'!$A:$D, 2, FALSE) & " (" & VLOOKUP(TEXT(Vi_SIM_Mobile[[#This Row],[Employee Code]],"00000"), 'EMP Info'!$A:$D,4, FALSE) & ")",""))) -> - | E33: =IF(Vi_SIM_Mobile[[#This Row],[Employee Code]]=0,"-",IFERROR(IF(INDEX('EMP Info'!$C:$C, MATCH(TEXT(Vi_SIM_Mobile[[#This Row],[Employee Code]],"00000"), 'EMP Info'!$A:$A, 0))=0,"",INDEX('EMP Info'!$C:$C, MATCH(TEXT(Vi_SIM_Mobile[[#This Row],[Employee Code]],"00000"), 'EMP Info'!$A:$A, 0))),IFERROR(VLOOKUP(TEXT(Vi_SIM_Mobile[[#This Row],[Employee Code]],"00000"), 'EMP Info'!$A:$D, 2, FALSE) & " (" & VLOOKUP(TEXT(Vi_SIM_Mobile[[#This Row],[Employee Code]],"00000"), 'EMP Info'!$A:$D,4, FALSE) & ")",""))) -> - | F33: D Block (Production) | I33: Basic Keypad Phone | J33: Nokia 105 | K33: 45572 | L33: =IFERROR(IF(Vi_SIM_Mobile[[#This Row],[Warranty Date]]<TODAY(), "Out of Warranty", IF(Vi_SIM_Mobile[[#This Row],[Warranty Date]]-TODAY()<=30, "Expiring Soon", "In Warranty")),"-") -> Out of Warranty | M33: =IFERROR(IF(Vi_SIM_Mobile[[#This Row],[Purchase Date]]="","NA",EDATE(Vi_SIM_Mobile[[#This Row],[Purchase Date]],12)),"NA") -> 45937 | S33: 89910274409014655027 | U33: Activated
A34: =ROW()-ROW(Vi_SIM_Mobile[[#Headers],[Sr. No.]]) -> 33 | B34: 9371109133 | C34: 0 | D34: =IF(Vi_SIM_Mobile[[#This Row],[Employee Code]]=0,"-",IFERROR(IF(INDEX('EMP Info'!$B:$B, MATCH(TEXT(Vi_SIM_Mobile[[#This Row],[Employee Code]],"00000"), 'EMP Info'!$A:$A, 0))=0,"",INDEX('EMP Info'!$B:$B, MATCH(TEXT(Vi_SIM_Mobile[[#This Row],[Employee Code]],"00000"), 'EMP Info'!$A:$A, 0))),IFERROR(VLOOKUP(TEXT(Vi_SIM_Mobile[[#This Row],[Employee Code]],"00000"), 'EMP Info'!$A:$D, 2, FALSE) & " (" & VLOOKUP(TEXT(Vi_SIM_Mobile[[#This Row],[Employee Code]],"00000"), 'EMP Info'!$A:$D,4, FALSE) & ")",""))) -> - | E34: =IF(Vi_SIM_Mobile[[#This Row],[Employee Code]]=0,"-",IFERROR(IF(INDEX('EMP Info'!$C:$C, MATCH(TEXT(Vi_SIM_Mobile[[#This Row],[Employee Code]],"00000"), 'EMP Info'!$A:$A, 0))=0,"",INDEX('EMP Info'!$C:$C, MATCH(TEXT(Vi_SIM_Mobile[[#This Row],[Employee Code]],"00000"), 'EMP Info'!$A:$A, 0))),IFERROR(VLOOKUP(TEXT(Vi_SIM_Mobile[[#This Row],[Employee Code]],"00000"), 'EMP Info'!$A:$D, 2, FALSE) & " (" & VLOOKUP(TEXT(Vi_SIM_Mobile[[#This Row],[Employee Code]],"00000"), 'EMP Info'!$A:$D,4, FALSE) & ")",""))) -> - | F34: Utility E 18 | I34: Basic Keypad Phone | J34: Nokia 105 | L34: =IFERROR(IF(Vi_SIM_Mobile[[#This Row],[Warranty Date]]<TODAY(), "Out of Warranty", IF(Vi_SIM_Mobile[[#This Row],[Warranty Date]]-TODAY()<=30, "Expiring Soon", "In Warranty")),"-") -> - | M34: =IFERROR(IF(Vi_SIM_Mobile[[#This Row],[Purchase Date]]="","NA",EDATE(Vi_SIM_Mobile[[#This Row],[Purchase Date]],12)),"NA") -> NA | S34: 89910274409014655050 | U34: Activated
A35: =ROW()-ROW(Vi_SIM_Mobile[[#Headers],[Sr. No.]]) -> 34 | B35: 9371109134 | C35: 0 | D35: E-16 Security Guard (Sunil Khawale) | E35: Security | F35: Security E16 | I35: Basic Keypad Phone | J35: HMD 105 4G | K35: 45882 | L35: =IFERROR(IF(Vi_SIM_Mobile[[#This Row],[Warranty Date]]<TODAY(), "Out of Warranty", IF(Vi_SIM_Mobile[[#This Row],[Warranty Date]]-TODAY()<=30, "Expiring Soon", "In Warranty")),"-") -> Out of Warranty | M35: =IFERROR(IF(Vi_SIM_Mobile[[#This Row],[Purchase Date]]="","NA",EDATE(Vi_SIM_Mobile[[#This Row],[Purchase Date]],12)),"NA") -> 46247 | N35: Chinmay Mobile Shopee | O35: 359926420837356 | P35: 359926425837351 | Q35: UA01000911003253240129480 | R35: Nano SIM | S35: 89910274409014655043 | U35: Activated
A36: =ROW()-ROW(Vi_SIM_Mobile[[#Headers],[Sr. No.]]) -> 35 | B36: 9371109135 | C36: 0 | D36: =IF(Vi_SIM_Mobile[[#This Row],[Employee Code]]=0,"-",IFERROR(IF(INDEX('EMP Info'!$B:$B, MATCH(TEXT(Vi_SIM_Mobile[[#This Row],[Employee Code]],"00000"), 'EMP Info'!$A:$A, 0))=0,"",INDEX('EMP Info'!$B:$B, MATCH(TEXT(Vi_SIM_Mobile[[#This Row],[Employee Code]],"00000"), 'EMP Info'!$A:$A, 0))),IFERROR(VLOOKUP(TEXT(Vi_SIM_Mobile[[#This Row],[Employee Code]],"00000"), 'EMP Info'!$A:$D, 2, FALSE) & " (" & VLOOKUP(TEXT(Vi_SIM_Mobile[[#This Row],[Employee Code]],"00000"), 'EMP Info'!$A:$D,4, FALSE) & ")",""))) -> - | E36: =IF(Vi_SIM_Mobile[[#This Row],[Employee Code]]=0,"-",IFERROR(IF(INDEX('EMP Info'!$C:$C, MATCH(TEXT(Vi_SIM_Mobile[[#This Row],[Employee Code]],"00000"), 'EMP Info'!$A:$A, 0))=0,"",INDEX('EMP Info'!$C:$C, MATCH(TEXT(Vi_SIM_Mobile[[#This Row],[Employee Code]],"00000"), 'EMP Info'!$A:$A, 0))),IFERROR(VLOOKUP(TEXT(Vi_SIM_Mobile[[#This Row],[Employee Code]],"00000"), 'EMP Info'!$A:$D, 2, FALSE) & " (" & VLOOKUP(TEXT(Vi_SIM_Mobile[[#This Row],[Employee Code]],"00000"), 'EMP Info'!$A:$D,4, FALSE) & ")",""))) -> - | F36: Shift Technician | I36: Basic Keypad Phone | J36: Nokia 105 | L36: =IFERROR(IF(Vi_SIM_Mobile[[#This Row],[Warranty Date]]<TODAY(), "Out of Warranty", IF(Vi_SIM_Mobile[[#This Row],[Warranty Date]]-TODAY()<=30, "Expiring Soon", "In Warranty")),"-") -> - | M36: =IFERROR(IF(Vi_SIM_Mobile[[#This Row],[Purchase Date]]="","NA",EDATE(Vi_SIM_Mobile[[#This Row],[Purchase Date]],12)),"NA") -> NA | S36: 89910274409014655035 | U36: Activated
A37: =ROW()-ROW(Vi_SIM_Mobile[[#Headers],[Sr. No.]]) -> 36 | B37: 9371109136 | C37: 106 | D37: =IF(Vi_SIM_Mobile[[#This Row],[Employee Code]]=0,"-",IFERROR(IF(INDEX('EMP Info'!$B:$B, MATCH(TEXT(Vi_SIM_Mobile[[#This Row],[Employee Code]],"00000"), 'EMP Info'!$A:$A, 0))=0,"",INDEX('EMP Info'!$B:$B, MATCH(TEXT(Vi_SIM_Mobile[[#This Row],[Employee Code]],"00000"), 'EMP Info'!$A:$A, 0))),IFERROR(VLOOKUP(TEXT(Vi_SIM_Mobile[[#This Row],[Employee Code]],"00000"), 'EMP Info'!$A:$D, 2, FALSE) & " (" & VLOOKUP(TEXT(Vi_SIM_Mobile[[#This Row],[Employee Code]],"00000"), 'EMP Info'!$A:$D,4, FALSE) & ")",""))) -> Ganesh Vitthal Tadaka | E37: =IF(Vi_SIM_Mobile[[#This Row],[Employee Code]]=0,"-",IFERROR(IF(INDEX('EMP Info'!$C:$C, MATCH(TEXT(Vi_SIM_Mobile[[#This Row],[Employee Code]],"00000"), 'EMP Info'!$A:$A, 0))=0,"",INDEX('EMP Info'!$C:$C, MATCH(TEXT(Vi_SIM_Mobile[[#This Row],[Employee Code]],"00000"), 'EMP Info'!$A:$A, 0))),IFERROR(VLOOKUP(TEXT(Vi_SIM_Mobile[[#This Row],[Employee Code]],"00000"), 'EMP Info'!$A:$D, 2, FALSE) & " (" & VLOOKUP(TEXT(Vi_SIM_Mobile[[#This Row],[Employee Code]],"00000"), 'EMP Info'!$A:$D,4, FALSE) & ")",""))) -> Production | F37: FG Store (Production Packing) | G37: - | H37: - | I37: Basic Keypad Phone | J37: HMD 105 4G | K37: 45935 | L37: =IFERROR(IF(Vi_SIM_Mobile[[#This Row],[Warranty Date]]<TODAY(), "Out of Warranty", IF(Vi_SIM_Mobile[[#This Row],[Warranty Date]]-TODAY()<=30, "Expiring Soon", "In Warranty")),"-") -> Expiring Soon | M37: =IFERROR(IF(Vi_SIM_Mobile[[#This Row],[Purchase Date]]="","NA",EDATE(Vi_SIM_Mobile[[#This Row],[Purchase Date]],12)),"NA") -> 46300 | N37: Chinmay Mobile Shopee | O37: 359926420827779 | P37: 359926425827774 | Q37: UA01000911003253240124651 | R37: Nano SIM | S37: 89910273509007898293 | U37: Activated
